Workbook
Name 回避: '49. リトル・マック'!$104:$110
Name 必殺技: '34. フシギソウ'!$52:$66
Name 回避: 'コピー'!$107:$113
Name 必殺技: '36. ディディーコング'!$58:$82
Name 共通動作: '55. パックマン'!$109:$137
Name 空中攻撃: '30. ワリオ'!$41:$52
Name 地上攻撃: '48. ロゼッタ&チコ'!$24:$57
Name つかみ・投げ: '69. ガオガエン'!$90:$107
Name つかみ・投げ: '70. パックンフラワー'!$87:$101
Name 行動フレーム・能力値: '66. リヒター'!$15:$22
Name 空中攻撃: '29. ゼロスーツサムス'!$45:$56
Name つかみ・投げ: '47. Wii Fit トレーナー'!$91:$105
Name 行動フレーム・能力値: '46. ロックマン'!$15:$22
Name 共通動作: '51. 格闘Mii'!$157:$185
Name 回避: '48. ロゼッタ&チコ'!$109:$115
Name 地上攻撃: '19. ピチュー'!$24:$37
Name 共通動作: '39. デデデ'!$112:$140
Name 共通動作: '49. リトル・マック'!$112:$140
Name 共通動作: '44. ウルフ'!$95:$123
Name 回避: '44. ウルフ'!$87:$93
Name つかみ・投げ: '40. ピクミン&オリマー'!$120:$144
Name 空中攻撃: '56. ルフレ'!$49:$69
Name 回避: '67. キングクルール'!$105:$111
Name 必殺技: '66. リヒター'!$56:$72
Name 地上攻撃: '64. インクリング'!$24:$50
Name 行動フレーム・能力値: '33. ゼニガメ'!$15:$22
Name 地上攻撃: '41. ルカリオ'!$32:$48
Name 回避: '40. ピクミン&オリマー'!$146:$152
Name 地上攻撃: '15. アイスクライマー'!$30:$42
Name つかみ・投げ: '57. シュルク'!$97:$111
Name 共通動作: '40. ピクミン&オリマー'!$154:$182
Name 共通動作: '70. パックンフラワー'!$111:$139
Name 必殺技: '31. スネーク'!$61:$90
Name つかみ・投げ: '46. ロックマン'!$95:$109
Name 回避: '46. ロックマン'!$111:$117
Name 共通動作: '66. シモン'!$97:$125
Name 必殺技: '57. シュルク'!$75:$95
Name 地上攻撃: '59. ダックハント'!$24:$45
Name 地上攻撃: '58. クッパ Jr.'!$24:$46
Name 回避: '56. ルフレ'!$116:$122
Name 共通動作: '69. ガオガエン'!$117:$145
Name 必殺技: '41. ルカリオ'!$62:$79
Name 地上攻撃: '67. キングクルール'!$24:$47
Name 行動フレーム・能力値: '41. ルカリオ'!$15:$22
Name 行動フレーム・能力値: '40. ピクミン&オリマー'!$15:$22
Name 必殺技: '51. 格闘Mii'!$54:$130
Name 行動フレーム・能力値: '70. パックンフラワー'!$15:$22
Name 必殺技: '58. クッパ Jr.'!$65:$88
Name つかみ・投げ: '50. ゲッコウガ'!$90:$104
Name 必殺技: '44. ウルフ'!$51:$67
Name 回避: '66. シモン'!$89:$95
Name 行動フレーム・能力値: '35. リザードン'!$15:$22
Name 共通動作: '45. むらびと'!$126:$154
Name つかみ・投げ: '68. しずえ'!$86:$100
Name 空中攻撃: '49. リトル・マック'!$46:$52
Name 回避: '57. シュルク'!$113:$119
Name 行動フレーム・能力値: '49. リトル・マック'!$15:$22
Name 地上攻撃: '39. デデデ'!$24:$43
Name 必殺技: '50. ゲッコウガ'!$63:$88
Name 行動フレーム・能力値: '30. ワリオ'!$15:$22

Sheet トップページ
A2: トップページ | G2: 主な編集者
G3: =HYPERLINK("https://twitter.com/Meshima_","@Meshima_") -> @Meshima_
G4: =HYPERLINK("https://twitter.com/gengar6tomo ","@gengar6tomo") -> @gengar6tomo
G5: =HYPERLINK("https://twitter.com/drafix570","@drafix570") -> @drafix570
A6: =HYPERLINK("https://www65.atwiki.jp/smashsp_kensyou/pages/46.html","軽量版シートまとめはこちら") -> 軽量版シートまとめはこちら
A7: =HYPERLINK("https://www65.atwiki.jp/smashsp_kensyou/","SP検証wiki") -> SP検証wiki | C7: =HYPERLINK("https://twitter.com/SmashSP_kensyou","Twitter") -> Twitter | E7: Discord | G7: =HYPERLINK("https://www.youtube.com/channel/UCzrAavy2PolObtI65CZE_cg/videos","Youtube") -> Youtube
A11: 利用方法
A12: ・画面左下の＋ボタンの右、「亖ボタン」から各ファイターのページに飛ぶことができます。 ・各ファイターページ上部にある「＋ボタン」をクリックすることで、詳細情報を開くことができます。
A15: ※初めての方は「必ず」読んでください
A18: リンクについて
A19: 当スプレッドシートはリンクフリー、掲載内容も転載自由です（免責事項をよくお読みください）。 転載の際は引用元として当wikiの名前を挙げていただけると幸いです。
A22: 免責事項
A23: 編集者は、当シートにコンテンツを掲載するにあたってその内容について細心の注意を払っておりますが、 コンテンツの内容が正確であるかどうか、最新のものであるかどうか等について保証をするものではなく、 何らかの責任を負うものではありません。 また、編集者は通知することなく当シートに掲載した情報の訂正、修正、追加、中断、削除等をいつでも 行うことができるものとします。当シート、またはコンテンツのご利用により、万一何らかの不都合や 損害が発生したとしても、責任は負いかねますのでご了承お願いいたします。
A29: 連絡・報告など
A30: お手数ですが、誤りなどを発見した場合にはTwitterやDiscord等で編集者に知らせていただければ幸いです。 また、不明な点があった場合にも同様の方法で編集者にコンタクトしていただければ返信いたします。
A33: 外部リンク
A34: =HYPERLINK("http://smashwiki.info/%E3%83%A1%E3%82%A4%E3%83%B3%E3%83%9A%E3%83%BC%E3%82%B8","大乱闘スマッシュブラザーズwiki") -> 大乱闘スマッシュブラザーズwiki | D34: 有志の方によるwiki。 キャラクター・アイテム・ステージ・ゲームモードなど、 幅広い情報を手に入れることができる。
A35: =HYPERLINK("https://rubendal.github.io/SSBU-Calculator/","Smash Ultimate Calculator [WIP]") -> Smash Ultimate Calculator [WIP] | D35: Ruben氏(@Ruben_dal)による計算サイト。 ヒットストップ・やられ硬直・硬直差などを逐一計算できる。
A37: シートの閲覧方法
A38: =HYPERLINK("https://i.imgur.com/hKGd2PV.png", "トップページ") -> トップページ
A39: =IMAGE("https://i.imgur.com/hKGd2PV.png",1) -> #REF!
A62: =HYPERLINK("https://i.imgur.com/hKGd2PV.png","ファイター個別ページ") -> ファイター個別ページ
A63: =IMAGE("https://i.imgur.com/UnjnBNK.png",1) -> #REF!
A88: =HYPERLINK("https://i.imgur.com/qAl8YPs.png","パラメータページ：並べ替え") -> パラメータページ：並べ替え
A89: =IMAGE("https://i.imgur.com/qAl8YPs.png",1) -> #REF!
A125: その他
D127: (M) 了解。 | H127: (M) できれば共有アカウントを使いたくない（切り替えがめんどい）ですし所有者はDRAFIXさんでいい気はします、メンバーには所有権譲渡で
B129: -> Discord自体の目的
C130: -> Kurogane鯖のように質問などを受け付ける
D131: (M) 人手がたりなさそうだが、仕様変更点報告チャンネルみたいなのはできれば欲しい
D132: (D) Discordは表・裏の2窓体制に。表の方をKH風の自由投稿窓にして、報告やTwitterまとめなどのチャンネルを設ける
D133: (M) 上と同じで表・裏のDiscord統一でいい気がします
D134: (D) 限定チャンネルが疎外感を生むかと思っての提案でしたが、確かに管理や裏メンバー勧誘などを考えると一窓のほうが楽ですね。統一しちゃいましょう。
A135: ・フレーム表以外の検証
B136: -> 少なくともRuben氏はふっとび関連、Arthur氏は回避関連はやるらしい
C137: (M) トレモを使って検証する場合、まずトレモに変な仕様がないかを調べる
C138: (M) 被らないように比較的細かいところを、まずはつかみ関連・投げ無敵・投げアーマー（Xのが復活してる様子）・受け身あたり
C139: (M) 体験版までに「forのこいくち操作マニュアル」を作成し、新作で変更点がないかしらみつぶしに調べる
C140: (D) ガード・ジャスガ、小ジャンプ攻撃。
C141: (D) 検証に役立つワザと仕様の確認。2Fスキップ、1F発生弱、シールド発生など。
...

Sheet 1. マリオ
A1: 1 | C1: =IMAGE(VLOOKUP($A$1,Fighters!A2:AI114,12,FALSE),1) -> #REF!
A2: =VLOOKUP($A$1,Fighters!$A$2:$AI$81,6,FALSE) -> #ec2320
A3: =VLOOKUP($A$1,Fighters!$A$2:$AI$81,14,FALSE) -> 1. マリオ
A4: =VLOOKUP($A$1,Fighters!$A$2:$AI$81,13,FALSE) -> 0
I6: 最終更新
H8: 44379.843
A11: 最終更新：
A15: 行動フレーム・能力値
C16: 行動フレーム | E16: 能力値 | G16: 滞空フレーム | K16: ='テンプレート'!K16 -> 能力値その他
A17: ='テンプレート'!A17 -> ジャンプ回数 | B17: 2回 | C17: ='テンプレート'!C17 -> ジャンプ踏切 | D17: {=IF(INDEX('行動フレーム・能力値'!$C$2:$AD$115, MATCH($A$1,'行動フレーム・能力値'!$A$2:$A$115,0), MATCH(C17,'行動フレーム・能力値'!$C$1:$AD$1,0))="-", "-", INDEX('行動フレーム・能力値'!$C$2:$AD$115, MATCH($A$1,'行動フレーム・能力値'!$A$2:$A$115,0), MATCH(C17,'行動フレーム・能力値'!$C$1:$AD$1,0))&"F")} -> 3F | E17: ='テンプレート'!E17 -> 体重 | F17: {=IF(INDEX('行動フレーム・能力値'!$C$2:$AD$115, MATCH($A$1,'行動フレーム・能力値'!$A$2:$A$115,0), MATCH(E17,'行動フレーム・能力値'!$C$1:$AD$1,0))="-", "-", INDEX('行動フレーム・能力値'!$C$2:$AD$115, MATCH($A$1,'行動フレーム・能力値'!$A$2:$A$115,0), MATCH(E17,'行動フレーム・能力値'!$C$1:$AD$1,0))&" ["&INDEX('行動フレーム・能力値'!$C$2:$AD$115, MATCH($A$1,'行動フレーム・能力値'!$A$2:$A$115,0), MATCH(E17,'行動フレーム・能力値'!$C$1:$AD$1,0)-1)&IF(AND(INDEX('行動フレーム・能力値'!$C$2:$AD$115, MATCH($A$1,'行動フレーム・能力値'!$A$2:$A$115,0), MATCH(E17,'行動フレーム・能力値'!$C$1:$AD$1,0)-1)>=11, INDEX('行動フレーム・能力値'!$C$2:$AD$115, MATCH($A$1,'行動フレーム・能力値'!$A$2:$A$115,0), MATCH(E17,'行動フレーム・能力値'!$C$1:$AD$1,0)-1)<=13),"th",CHOOSE(MIN(5,RIGHT(INDEX('行動フレーム・能力値'!$C$2:$AD$115, MATCH($A$1,'行動フレーム・能力値'!$A$2:$A$115,0), MATCH(E17,'行動フレーム・能力値'!$C$1:$AD$1,0)-1))+1),"th","st","nd","rd","th"))&"]")} -> 98 [33rd] | G17: ='テンプレート'!G17 -> 小J滞空 | H17: {=IF(INDEX('行動フレーム・能力値'!$C$2:$AD$115, MATCH($A$1,'行動フレーム・能力値'!$A$2:$A$115,0), MATCH(G17,'行動フレーム・能力値'!$C$1:$AD$1,0))="-", "-", INDEX('行動フレーム・能力値'!$C$2:$AD$115, MATCH($A$1,'行動フレーム・能力値'!$A$2:$A$115,0), MATCH(G17,'行動フレーム・能力値'!$C$1:$AD$1,0))&"F")} -> 40F | K17: ='テンプレート'!K17 -> ダッシュ初速 | L17: {=IF(INDEX('能力値その他'!$C$2:$AD$115, MATCH($A$1,'能力値その他'!$A$2:$A$115,0), MATCH(K17,'能力値その他'!$C$1:$AD$1,0))="-", "-", INDEX('能力値その他'!$C$2:$AD$115, MATCH($A$1,'能力値その他'!$A$2:$A$115,0), MATCH(K17,'能力値その他'!$C$1:$AD$1,0))&" ["&INDEX('能力値その他'!$C$2:$AD$115, MATCH($A$1,'能力値その他'!$A$2:$A$115,0), MATCH(K17,'能力値その他'!$C$1:$AD$1,0)-1)&IF(AND(INDEX('能力値その他'!$C$2:$AD$115, MATCH($A$1,'能力値その他'!$A$2:$A$115,0), MATCH(K17,'能力値その他'!$C$1:$AD$1,0)-1)>=11, INDEX('能力値その他'!$C$2:$AD$115, MATCH($A$1,'能力値その他'!$A$2:$A$115,0), MATCH(K17,'能力値その他'!$C$1:$AD$1,0)-1)<=13),"th",CHOOSE(MIN(5,RIGHT(INDEX('能力値その他'!$C$2:$AD$115, MATCH($A$1,'能力値その他'!$A$2:$A$115,0), MATCH(K17,'能力値その他'!$C$1:$AD$1,0)-1))+1),"th","st","nd","rd","th"))&"]")} -> 1.936 [38th] | M17: ='テンプレート'!M17 -> 大J初速 | N17: {=IF(INDEX('能力値その他'!$C$2:$AD$115, MATCH($A$1,'能力値その他'!$A$2:$A$115,0), MATCH(M17,'能力値その他'!$C$1:$AD$1,0))="-", "-", INDEX('能力値その他'!$C$2:$AD$115, MATCH($A$1,'能力値その他'!$A$2:$A$115,0), MATCH(M17,'能力値その他'!$C$1:$AD$1,0))&" ["&INDEX('能力値その他'!$C$2:$AD$115, MATCH($A$1,'能力値その他'!$A$2:$A$115,0), MATCH(M17,'能力値その他'!$C$1:$AD$1,0)-1)&IF(AND(INDEX('能力値その他'!$C$2:$AD$115, MATCH($A$1,'能力値その他'!$A$2:$A$115,0), MATCH(M17,'能力値その他'!$C$1:$AD$1,0)-1)>=11, INDEX('能力値その他'!$C$2:$AD$115, MATCH($A$1,'能力値その他'!$A$2:$A$115,0), MATCH(M17,'能力値その他'!$C$1:$AD$1,0)-1)<=13),"th",CHOOSE(MIN(5,RIGHT(INDEX('能力値その他'!$C$2:$AD$115, MATCH($A$1,'能力値その他'!$A$2:$A$115,0), MATCH(M17,'能力値その他'!$C$1:$AD$1,0)-1))+1),"th","st","nd","rd","th"))&"]")} -> -
A18: ='テンプレート'!A18 -> しゃがみ歩き | B18: FALSE | C18: ='テンプレート'!C18 -> 小着地 | D18: {=IF(INDEX('行動フレーム・能力値'!$C$2:$AD$115, MATCH($A$1,'行動フレーム・能力値'!$A$2:$A$115,0), MATCH(C18,'行動フレーム・能力値'!$C$1:$AD$1,0))="-", "-", INDEX('行動フレーム・能力値'!$C$2:$AD$115, MATCH($A$1,'行動フレーム・能力値'!$A$2:$A$115,0), MATCH(C18,'行動フレーム・能力値'!$C$1:$AD$1,0))&"F")} -> 2F | E18: ='テンプレート'!E18 -> 歩行速度 | F18: {=IF(INDEX('行動フレーム・能力値'!$C$2:$AD$115, MATCH($A$1,'行動フレーム・能力値'!$A$2:$A$115,0), MATCH(E18,'行動フレーム・能力値'!$C$1:$AD$1,0))="-", "-", INDEX('行動フレーム・能力値'!$C$2:$AD$115, MATCH($A$1,'行動フレーム・能力値'!$A$2:$A$115,0), MATCH(E18,'行動フレーム・能力値'!$C$1:$AD$1,0))&" ["&INDEX('行動フレーム・能力値'!$C$2:$AD$115, MATCH($A$1,'行動フレーム・能力値'!$A$2:$A$115,0), MATCH(E18,'行動フレーム・能力値'!$C$1:$AD$1,0)-1)&IF(AND(INDEX('行動フレーム・能力値'!$C$2:$AD$115, MATCH($A$1,'行動フレーム・能力値'!$A$2:$A$115,0), MATCH(E18,'行動フレーム・能力値'!$C$1:$AD$1,0)-1)>=11, INDEX('行動フレーム・能力値'!$C$2:$AD$115, MATCH($A$1,'行動フレーム・能力値'!$A$2:$A$115,0), MATCH(E18,'行動フレーム・能力値'!$C$1:$AD$1,0)-1)<=13),"th",CHOOSE(MIN(5,RIGHT(INDEX('行動フレーム・能力値'!$C$2:$AD$115, MATCH($A$1,'行動フレーム・能力値'!$A$2:$A$115,0), MATCH(E18,'行動フレーム・能力値'!$C$1:$AD$1,0)-1))+1),"th","st","nd","rd","th"))&"]")} -> 1.155 [35th] | G18: ='テンプレート'!G18 -> 大J滞空 | H18: {=IF(INDEX('行動フレーム・能力値'!$C$2:$AD$115, MATCH($A$1,'行動フレーム・能力値'!$A$2:$A$115,0), MATCH(G18,'行動フレーム・能力値'!$C$1:$AD$1,0))="-", "-", INDEX('行動フレーム・能力値'!$C$2:$AD$115, MATCH($A$1,'行動フレーム・能力値'!$A$2:$A$115,0), MATCH(G18,'行動フレーム・能力値'!$C$1:$AD$1,0))&"F")} -> 56F | K18: ='テンプレート'!K18 -> 走行加速 | L18: {=IF(INDEX('能力値その他'!$C$2:$AD$115, MATCH($A$1,'能力値その他'!$A$2:$A$115,0), MATCH(K18,'能力値その他'!$C$1:$AD$1,0))="-", "-", INDEX('能力値その他'!$C$2:$AD$115, MATCH($A$1,'能力値その他'!$A$2:$A$115,0), MATCH(K18,'能力値その他'!$C$1:$AD$1,0))&" ["&INDEX('能力値その他'!$C$2:$AD$115, MATCH($A$1,'能力値その他'!$A$2:$A$115,0), MATCH(K18,'能力値その他'!$C$1:$AD$1,0)-1)&IF(AND(INDEX('能力値その他'!$C$2:$AD$115, MATCH($A$1,'能力値その他'!$A$2:$A$115,0), MATCH(K18,'能力値その他'!$C$1:$AD$1,0)-1)>=11, INDEX('能力値その他'!$C$2:$AD$115, MATCH($A$1,'能力値その他'!$A$2:$A$115,0), MATCH(K18,'能力値その他'!$C$1:$AD$1,0)-1)<=13),"th",CHOOSE(MIN(5,RIGHT(INDEX('能力値その他'!$C$2:$AD$115, MATCH($A$1,'能力値その他'!$A$2:$A$115,0), MATCH(K18,'能力値その他'!$C$1:$AD$1,0)-1))+1),"th","st","nd","rd","th"))&"]")} -> 0.15378 [27th] | M18: ='テンプレート'!M18 -> 大J高度 | N18: {=IF(INDEX('能力値その他'!$C$2:$AD$115, MATCH($A$1,'能力値その他'!$A$2:$A$115,0), MATCH(M18,'能力値その他'!$C$1:$AD$1,0))="-", "-", INDEX('能力値その他'!$C$2:$AD$115, MATCH($A$1,'能力値その他'!$A$2:$A$115,0), MATCH(M18,'能力値その他'!$C$1:$AD$1,0))&" ["&INDEX('能力値その他'!$C$2:$AD$115, MATCH($A$1,'能力値その他'!$A$2:$A$115,0), MATCH(M18,'能力値その他'!$C$1:$AD$1,0)-1)&IF(AND(INDEX('能力値その他'!$C$2:$AD$115, MATCH($A$1,'能力値その他'!$A$2:$A$115,0), MATCH(M18,'能力値その他'!$C$1:$AD$1,0)-1)>=11, INDEX('能力値その他'!$C$2:$AD$115, MATCH($A$1,'能力値その他'!$A$2:$A$115,0), MATCH(M18,'能力値その他'!$C$1:$AD$1,0)-1)<=13),"th",CHOOSE(MIN(5,RIGHT(INDEX('能力値その他'!$C$2:$AD$115, MATCH($A$1,'能力値その他'!$A$2:$A$115,0), MATCH(M18,'能力値その他'!$C$1:$AD$1,0)-1))+1),"th","st","nd","rd","th"))&"]")} -> 36.33 [16th]
A19: ='テンプレート'!A19 -> カベジャンプ | B19: TRUE | C19: ='テンプレート'!C19 -> 大着地 | D19: {=IF(INDEX('行動フレーム・能力値'!$C$2:$AD$115, MATCH($A$1,'行動フレーム・能力値'!$A$2:$A$115,0), MATCH(C19,'行動フレーム・能力値'!$C$1:$AD$1,0))="-", "-", INDEX('行動フレーム・能力値'!$C$2:$AD$115, MATCH($A$1,'行動フレーム・能力値'!$A$2:$A$115,0), MATCH(C19,'行動フレーム・能力値'!$C$1:$AD$1,0))&"F")} -> 4F | E19: ='テンプレート'!E19 -> 走行速度 | F19: {=IF(INDEX('行動フレーム・能力値'!$C$2:$AD$115, MATCH($A$1,'行動フレーム・能力値'!$A$2:$A$115,0), MATCH(E19,'行動フレーム・能力値'!$C$1:$AD$1,0))="-", "-", INDEX('行動フレーム・能力値'!$C$2:$AD$115, MATCH($A$1,'行動フレーム・能力値'!$A$2:$A$115,0), MATCH(E19,'行動フレーム・能力値'!$C$1:$AD$1,0))&" ["&INDEX('行動フレーム・能力値'!$C$2:$AD$115, MATCH($A$1,'行動フレーム・能力値'!$A$2:$A$115,0), MATCH(E19,'行動フレーム・能力値'!$C$1:$AD$1,0)-1)&IF(AND(INDEX('行動フレーム・能力値'!$C$2:$AD$115, MATCH($A$1,'行動フレーム・能力値'!$A$2:$A$115,0), MATCH(E19,'行動フレーム・能力値'!$C$1:$AD$1,0)-1)>=11, INDEX('行動フレーム・能力値'!$C$2:$AD$115, MATCH($A$1,'行動フレーム・能力値'!$A$2:$A$115,0), MATCH(E19,'行動フレーム・能力値'!$C$1:$AD$1,0)-1)<=13),"th",CHOOSE(MIN(5,RIGHT(INDEX('行動フレーム・能力値'!$C$2:$AD$115, MATCH($A$1,'行動フレーム・能力値'!$A$2:$A$115,0), MATCH(E19,'行動フレーム・能力値'!$C$1:$AD$1,0)-1))+1),"th","st","nd","rd","th"))&"]")} -> 1.76 [37th] | G19: ='テンプレート'!G19 -> 小J急降下滞空 | H19: {=IF(INDEX('行動フレーム・能力値'!$C$2:$AD$115, MATCH($A$1,'行動フレーム・能力値'!$A$2:$A$115,0), MATCH(G19,'行動フレーム・能力値'!$C$1:$AD$1,0))="-", "-", INDEX('行動フレーム・能力値'!$C$2:$AD$115, MATCH($A$1,'行動フレーム・能力値'!$A$2:$A$115,0), MATCH(G19,'行動フレーム・能力値'!$C$1:$AD$1,0))&"F")} -> 28F | K19: ='テンプレート'!K19 -> 地上抵抗 | L19: {=IF(INDEX('能力値その他'!$C$2:$AD$115, MATCH($A$1,'能力値その他'!$A$2:$A$115,0), MATCH(K19,'能力値その他'!$C$1:$AD$1,0))="-", "-", INDEX('能力値その他'!$C$2:$AD$115, MATCH($A$1,'能力値その他'!$A$2:$A$115,0), MATCH(K19,'能力値その他'!$C$1:$AD$1,0))&" ["&INDEX('能力値その他'!$C$2:$AD$115, MATCH($A$1,'能力値その他'!$A$2:$A$115,0), MATCH(K19,'能力値その他'!$C$1:$AD$1,0)-1)&IF(AND(INDEX('能力値その他'!$C$2:$AD$115, MATCH($A$1,'能力値その他'!$A$2:$A$115,0), MATCH(K19,'能力値その他'!$C$1:$AD$1,0)-1)>=11, INDEX('能力値その他'!$C$2:$AD$115, MATCH($A$1,'能力値その他'!$A$2:$A$115,0), MATCH(K19,'能力値その他'!$C$1:$AD$1,0)-1)<=13),"th",CHOOSE(MIN(5,RIGHT(INDEX('能力値その他'!$C$2:$AD$115, MATCH($A$1,'能力値その他'!$A$2:$A$115,0), MATCH(K19,'能力値その他'!$C$1:$AD$1,0)-1))+1),"th","st","nd","rd","th"))&"]")} -> 0.102 [61st] | M19: ='テンプレート'!M19 -> 小J高度 | N19: {=IF(INDEX('能力値その他'!$C$2:$AD$115, MATCH($A$1,'能力値その他'!$A$2:$A$115,0), MATCH(M19,'能力値その他'!$C$1:$AD$1,0))="-", "-", INDEX('能力値その他'!$C$2:$AD$115, MATCH($A$1,'能力値その他'!$A$2:$A$115,0), MATCH(M19,'能力値その他'!$C$1:$AD$1,0))&" ["&INDEX('能力値その他'!$C$2:$AD$115, MATCH($A$1,'能力値その他'!$A$2:$A$115,0), MATCH(M19,'能力値その他'!$C$1:$AD$1,0)-1)&IF(AND(INDEX('能力値その他'!$C$2:$AD$115, MATCH($A$1,'能力値その他'!$A$2:$A$115,0), MATCH(M19,'能力値その他'!$C$1:$AD$1,0)-1)>=11, INDEX('能力値その他'!$C$2:$AD$115, MATCH($A$1,'能力値その他'!$A$2:$A$115,0), MATCH(M19,'能力値その他'!$C$1:$AD$1,0)-1)<=13),"th",CHOOSE(MIN(5,RIGHT(INDEX('能力値その他'!$C$2:$AD$115, MATCH($A$1,'能力値その他'!$A$2:$A$115,0), MATCH(M19,'能力値その他'!$C$1:$AD$1,0)-1))+1),"th","st","nd","rd","th"))&"]")} -> 17.54 [16th]
A20: ='テンプレート'!A20 -> カベ張りつき | B20: FALSE | C20: 走行移行前F | D20: {=IF(INDEX('行動フレーム・能力値'!$C$2:$AD$115, MATCH($A$1,'行動フレーム・能力値'!$A$2:$A$115,0), MATCH(C20,'行動フレーム・能力値'!$C$1:$AD$1,0))="-", "-", INDEX('行動フレーム・能力値'!$C$2:$AD$115, MATCH($A$1,'行動フレーム・能力値'!$A$2:$A$115,0), MATCH(C20,'行動フレーム・能力値'!$C$1:$AD$1,0))&"F ["&INDEX('行動フレーム・能力値'!$C$2:$AD$115, MATCH($A$1,'行動フレーム・能力値'!$A$2:$A$115,0), MATCH(C20,'行動フレーム・能力値'!$C$1:$AD$1,0)-1)&IF(AND(INDEX('行動フレーム・能力値'!$C$2:$AD$115, MATCH($A$1,'行動フレーム・能力値'!$A$2:$A$115,0), MATCH(C20,'行動フレーム・能力値'!$C$1:$AD$1,0)-1)>=11, INDEX('行動フレーム・能力値'!$C$2:$AD$115, MATCH($A$1,'行動フレーム・能力値'!$A$2:$A$115,0), MATCH(C20,'行動フレーム・能力値'!$C$1:$AD$1,0)-1)<=13),"th",CHOOSE(MIN(5,RIGHT(INDEX('行動フレーム・能力値'!$C$2:$AD$115, MATCH($A$1,'行動フレーム・能力値'!$A$2:$A$115,0), MATCH(C20,'行動フレーム・能力値'!$C$1:$AD$1,0)-1))+1),"th","st","nd","rd","th"))&"]")} -> 10F [5th] | E20: ='テンプレート'!E20 -> 空中速度 | F20: {=IF(INDEX('行動フレーム・能力値'!$C$2:$AD$115, MATCH($A$1,'行動フレーム・能力値'!$A$2:$A$115,0), MATCH(E20,'行動フレーム・能力値'!$C$1:$AD$1,0))="-", "-", INDEX('行動フレーム・能力値'!$C$2:$AD$115, MATCH($A$1,'行動フレーム・能力値'!$A$2:$A$115,0), MATCH(E20,'行動フレーム・能力値'!$C$1:$AD$1,0))&" ["&INDEX('行動フレーム・能力値'!$C$2:$AD$115, MATCH($A$1,'行動フレーム・能力値'!$A$2:$A$115,0), MATCH(E20,'行動フレーム・能力値'!$C$1:$AD$1,0)-1)&IF(AND(INDEX('行動フレーム・能力値'!$C$2:$AD$115, MATCH($A$1,'行動フレーム・能力値'!$A$2:$A$115,0), MATCH(E20,'行動フレーム・能力値'!$C$1:$AD$1,0)-1)>=11, INDEX('行動フレーム・能力値'!$C$2:$AD$115, MATCH($A$1,'行動フレーム・能力値'!$A$2:$A$115,0), MATCH(E20,'行動フレーム・能力値'!$C$1:$AD$1,0)-1)<=13),"th",CHOOSE(MIN(5,RIGHT(INDEX('行動フレーム・能力値'!$C$2:$AD$115, MATCH($A$1,'行動フレーム・能力値'!$A$2:$A$115,0), MATCH(E20,'行動フレーム・能力値'!$C$1:$AD$1,0)-1))+1),"th","st","nd","rd","th"))&"]")} -> 1.208 [13th] | G20: ='テンプレート'!G20 -> 大J急降下滞空 | H20: {=IF(INDEX('行動フレーム・能力値'!$C$2:$AD$115, MATCH($A$1,'行動フレーム・能力値'!$A$2:$A$115,0), MATCH(G20,'行動フレーム・能力値'!$C$1:$AD$1,0))="-", "-", INDEX('行動フレーム・能力値'!$C$2:$AD$115, MATCH($A$1,'行動フレーム・能力値'!$A$2:$A$115,0), MATCH(G20,'行動フレーム・能力値'!$C$1:$AD$1,0))&"F")} -> 39F | K20: ='テンプレート'!K20 -> 空中加速 | L20: {=IF(INDEX('能力値その他'!$C$2:$AD$115, MATCH($A$1,'能力値その他'!$A$2:$A$115,0), MATCH(K20,'能力値その他'!$C$1:$AD$1,0))="-", "-", INDEX('能力値その他'!$C$2:$AD$115, MATCH($A$1,'能力値その他'!$A$2:$A$115,0), MATCH(K20,'能力値その他'!$C$1:$AD$1,0))&" ["&INDEX('能力値その他'!$C$2:$AD$115, MATCH($A$1,'能力値その他'!$A$2:$A$115,0), MATCH(K20,'能力値その他'!$C$1:$AD$1,0)-1)&IF(AND(INDEX('能力値その他'!$C$2:$AD$115, MATCH($A$1,'能力値その他'!$A$2:$A$115,0), MATCH(K20,'能力値その他'!$C$1:$AD$1,0)-1)>=11, INDEX('能力値その他'!$C$2:$AD$115, MATCH($A$1,'能力値その他'!$A$2:$A$115,0), MATCH(K20,'能力値その他'!$C$1:$AD$1,0)-1)<=13),"th",CHOOSE(MIN(5,RIGHT(INDEX('能力値その他'!$C$2:$AD$115, MATCH($A$1,'能力値その他'!$A$2:$A$115,0), MATCH(K20,'能力値その他'!$C$1:$AD$1,0)-1))+1),"th","st","nd","rd","th"))&"]")} -> 0.08 [31st] | M20: ='テンプレート'!M20 -> 空中J高度 | N20: {=IF(INDEX('能力値その他'!$C$2:$AD$115, MATCH($A$1,'能力値その他'!$A$2:$A$115,0), MATCH(M20,'能力値その他'!$C$1:$AD$1,0))="-", "-", INDEX('能力値その他'!$C$2:$AD$115, MATCH($A$1,'能力値その他'!$A$2:$A$115,0), MATCH(M20,'能力値その他'!$C$1:$AD$1,0))&" ["&INDEX('能力値その他'!$C$2:$AD$115, MATCH($A$1,'能力値その他'!$A$2:$A$115,0), MATCH(M20,'能力値その他'!$C$1:$AD$1,0)-1)&IF(AND(INDEX('能力値その他'!$C$2:$AD$115, MATCH($A$1,'能力値その他'!$A$2:$A$115,0), MATCH(M20,'能力値その他'!$C$1:$AD$1,0)-1)>=11, INDEX('能力値その他'!$C$2:$AD$115, MATCH($A$1,'能力値その他'!$A$2:$A$115,0), MATCH(M20,'能力値その他'!$C$1:$AD$1,0)-1)<=13),"th",CHOOSE(MIN(5,RIGHT(INDEX('能力値その他'!$C$2:$AD$115, MATCH($A$1,'能力値その他'!$A$2:$A$115,0), MATCH(M20,'能力値その他'!$C$1:$AD$1,0)-1))+1),"th","st","nd","rd","th"))&"]")} -> 36.33 [22nd]
A21: ='テンプレート'!A21 -> 空中ワイヤー | B21: FALSE | C21: ='テンプレート'!C21 -> ステップ全体F | D21: {=IF(INDEX('行動フレーム・能力値'!$C$2:$AD$115, MATCH($A$1,'行動フレーム・能力値'!$A$2:$A$115,0), MATCH(C21,'行動フレーム・能力値'!$C$1:$AD$1,0))="-", "-", INDEX('行動フレーム・能力値'!$C$2:$AD$115, MATCH($A$1,'行動フレーム・能力値'!$A$2:$A$115,0), MATCH(C21,'行動フレーム・能力値'!$C$1:$AD$1,0))&"F ["&INDEX('行動フレーム・能力値'!$C$2:$AD$115, MATCH($A$1,'行動フレーム・能力値'!$A$2:$A$115,0), MATCH(C21,'行動フレーム・能力値'!$C$1:$AD$1,0)-1)&IF(AND(INDEX('行動フレーム・能力値'!$C$2:$AD$115, MATCH($A$1,'行動フレーム・能力値'!$A$2:$A$115,0), MATCH(C21,'行動フレーム・能力値'!$C$1:$AD$1,0)-1)>=11, INDEX('行動フレーム・能力値'!$C$2:$AD$115, MATCH($A$1,'行動フレーム・能力値'!$A$2:$A$115,0), MATCH(C21,'行動フレーム・能力値'!$C$1:$AD$1,0)-1)<=13),"th",CHOOSE(MIN(5,RIGHT(INDEX('行動フレーム・能力値'!$C$2:$AD$115, MATCH($A$1,'行動フレーム・能力値'!$A$2:$A$115,0), MATCH(C21,'行動フレーム・能力値'!$C$1:$AD$1,0)-1))+1),"th","st","nd","rd","th"))&"]")} -> 19F [13th] | E21: ='テンプレート'!E21 -> 落下速度 | F21: {=IF(INDEX('行動フレーム・能力値'!$C$2:$AD$115, MATCH($A$1,'行動フレーム・能力値'!$A$2:$A$115,0), MATCH(E21,'行動フレーム・能力値'!$C$1:$AD$1,0))="-", "-", INDEX('行動フレーム・能力値'!$C$2:$AD$115, MATCH($A$1,'行動フレーム・能力値'!$A$2:$A$115,0), MATCH(E21,'行動フレーム・能力値'!$C$1:$AD$1,0))&" ["&INDEX('行動フレーム・能力値'!$C$2:$AD$115, MATCH($A$1,'行動フレーム・能力値'!$A$2:$A$115,0), MATCH(E21,'行動フレーム・能力値'!$C$1:$AD$1,0)-1)&IF(AND(INDEX('行動フレーム・能力値'!$C$2:$AD$115, MATCH($A$1,'行動フレーム・能力値'!$A$2:$A$115,0), MATCH(E21,'行動フレーム・能力値'!$C$1:$AD$1,0)-1)>=11, INDEX('行動フレーム・能力値'!$C$2:$AD$115, MATCH($A$1,'行動フレーム・能力値'!$A$2:$A$115,0), MATCH(E21,'行動フレーム・能力値'!$C$1:$AD$1,0)-1)<=13),"th",CHOOSE(MIN(5,RIGHT(INDEX('行動フレーム・能力値'!$C$2:$AD$115, MATCH($A$1,'行動フレーム・能力値'!$A$2:$A$115,0), MATCH(E21,'行動フレーム・能力値'!$C$1:$AD$1,0)-1))+1),"th","st","nd","rd","th"))&"]")} -> 1.5 [59th] | K21: ='テンプレート'!K21 -> 空中抵抗 | L21: {=IF(INDEX('能力値その他'!$C$2:$AD$115, MATCH($A$1,'能力値その他'!$A$2:$A$115,0), MATCH(K21,'能力値その他'!$C$1:$AD$1,0))="-", "-", INDEX('能力値その他'!$C$2:$AD$115, MATCH($A$1,'能力値その他'!$A$2:$A$115,0), MATCH(K21,'能力値その他'!$C$1:$AD$1,0))&" ["&INDEX('能力値その他'!$C$2:$AD$115, MATCH($A$1,'能力値その他'!$A$2:$A$115,0), MATCH(K21,'能力値その他'!$C$1:$AD$1,0)-1)&IF(AND(INDEX('能力値その他'!$C$2:$AD$115, MATCH($A$1,'能力値その他'!$A$2:$A$115,0), MATCH(K21,'能力値その他'!$C$1:$AD$1,0)-1)>=11, INDEX('能力値その他'!$C$2:$AD$115, MATCH($A$1,'能力値その他'!$A$2:$A$115,0), MATCH(K21,'能力値その他'!$C$1:$AD$1,0)-1)<=13),"th",CHOOSE(MIN(5,RIGHT(INDEX('能力値その他'!$C$2:$AD$115, MATCH($A$1,'能力値その他'!$A$2:$A$115,0), MATCH(K21,'能力値その他'!$C$1:$AD$1,0)-1))+1),"th","st","nd","rd","th"))&"]")} -> 0.015 [9th]
E22: ='テンプレート'!E22 -> 急降下速度 | F22: {=IF(INDEX('行動フレーム・能力値'!$C$2:$AD$115, MATCH($A$1,'行動フレーム・能力値'!$A$2:$A$115,0), MATCH(E22,'行動フレーム・能力値'!$C$1:$AD$1,0))="-", "-", INDEX('行動フレーム・能力値'!$C$2:$AD$115, MATCH($A$1,'行動フレーム・能力値'!$A$2:$A$115,0), MATCH(E22,'行動フレーム・能力値'!$C$1:$AD$1,0))&" ["&INDEX('行動フレーム・能力値'!$C$2:$AD$115, MATCH($A$1,'行動フレーム・能力値'!$A$2:$A$115,0), MATCH(E22,'行動フレーム・能力値'!$C$1:$AD$1,0)-1)&IF(AND(INDEX('行動フレーム・能力値'!$C$2:$AD$115, MATCH($A$1,'行動フレーム・能力値'!$A$2:$A$115,0), MATCH(E22,'行動フレーム・能力値'!$C$1:$AD$1,0)-1)>=11, INDEX('行動フレーム・能力値'!$C$2:$AD$115, MATCH($A$1,'行動フレーム・能力値'!$A$2:$A$115,0), MATCH(E22,'行動フレーム・能力値'!$C$1:$AD$1,0)-1)<=13),"th",CHOOSE(MIN(5,RIGHT(INDEX('行動フレーム・能力値'!$C$2:$AD$115, MATCH($A$1,'行動フレーム・能力値'!$A$2:$A$115,0), MATCH(E22,'行動フレーム・能力値'!$C$1:$AD$1,0)-1))+1),"th","st","nd","rd","th"))&"]")} -> 2.4 [57th] | K22: ='テンプレート'!K22 -> 重力 | L22: {=IF(INDEX('能力値その他'!$C$2:$AD$115, MATCH($A$1,'能力値その他'!$A$2:$A$115,0), MATCH(K22,'能力値その他'!$C$1:$AD$1,0))="-", "-", INDEX('能力値その他'!$C$2:$AD$115, MATCH($A$1,'能力値その他'!$A$2:$A$115,0), MATCH(K22,'能力値その他'!$C$1:$AD$1,0))&" ["&INDEX('能力値その他'!$C$2:$AD$115, MATCH($A$1,'能力値その他'!$A$2:$A$115,0), MATCH(K22,'能力値その他'!$C$1:$AD$1,0)-1)&IF(AND(INDEX('能力値その他'!$C$2:$AD$115, MATCH($A$1,'能力値その他'!$A$2:$A$115,0), MATCH(K22,'能力値その他'!$C$1:$AD$1,0)-1)>=11, INDEX('能力値その他'!$C$2:$AD$115, MATCH($A$1,'能力値その他'!$A$2:$A$115,0), MATCH(K22,'能力値その他'!$C$1:$AD$1,0)-1)<=13),"th",CHOOSE(MIN(5,RIGHT(INDEX('能力値その他'!$C$2:$AD$115, MATCH($A$1,'能力値その他'!$A$2:$A$115,0), MATCH(K22,'能力値その他'!$C$1:$AD$1,0)-1))+1),"th","st","nd","rd","th"))&"]")} -> 0.087 [54th]
A24: 地上攻撃
C25: 判定持続 | D25: 全体フレーム | E25: 基礎ダメージ | F25: ダメージ (1v1) | G25: ガード硬直 | H25: 備考 | K25: ='テンプレート'!K25 -> ベクトル | L25: ='テンプレート'!L25 -> KBG (R.E.) | M25: ='テンプレート'!M25 -> BKB (R.A.) | N25: ='テンプレート'!N25 -> FKB (R.F.) | O25: ='テンプレート'!O25 -> 盾削り値 | P25: ='テンプレート'!P25 -> ﾋｯﾄｽﾄｯﾌﾟ | Q25: ='テンプレート'!Q25 -> ずらし | U25: 慣性消去
A26: ='テンプレート'!A26 -> 弱攻撃 | B26: 弱1 | C26: 2-3 | D26: 19 (6) | E26: 2.2 | F26: 2.64 | G26: 3F | H26: 5-24Fは弱2に移行可能。 空振り時にボタン長押しで7F目から弱1でキャンセル可能。 | U26: なし
B27: 弱2 | C27: 2-3 | D27: 21 | E27: 1.7 | F27: 2.04 | G27: 3F | H27: 6-24Fは弱3に移行可能。 | U27: 1F
B28: 弱3 | C28: 3-4 | D28: 33 | E28: 4 | F28: 4.8 | G28: 5F | U28: -
A29: ダッシュ攻撃 | C29: 6-9 | D29: 37 | E29: 8 | F29: 9.6 | G29: 14F | H29: ガード硬直補正倍率：1.875倍 | U29: 1F
B30: 持続 | C30: 10-25 | E30: 6 | F30: 7.2 | G30: 11F
A31: 横強 | B31: 全シフト | C31: 5-7 | D31: 25 | E31: 7 | F31: 8.4 | G31: 7F | U31: 1F(*)
A32: 上強 | C32: 5-11 | D32: 29 | E32: 5.5 | F32: 6.6 | G32: 6F | U32: なし
A33: 下強 | C33: 5-7 | D33: 27 | E33: 7/5 | F33: 8.4/6 | G33: 7F/6F | U33: なし
A34: 横スマッシュ | B34: 全シフト | C34: 15-17 | D34: 47 | E34: 14.7/17.8 | F34: 17.64/21.36 | G34: 10F/12F | H34: 先端のみ相殺なし。 溜め開始：6F目 | U34: 7F
A35: 上スマッシュ | C35: 9-12 | D35: 39 | E35: 14 | F35: 16.8 | G35: 10F | H35: 頭無敵：9-12F ぬるり判定消去：7-19F 溜め開始：7F目 | U35: 8F
A36: 下スマッシュ | B36: Hit 1 | C36: 5-6 | D36: 43 | E36: 10 | F36: 12 | G36: 7F | H36: 溜め開始：3F目 | U36: なし
B37: Hit 2 | C37: 14 | E37: 12 | F37: 14.4 | G37: 8F
A39: 空中攻撃
C40: 判定持続 | D40: 全体フレーム | E40: 基礎ダメージ | F40: ダメージ (1v1) | G40: ダメ (1v1+小J) | H40: ガード硬直 | I40: 着地隙 | J40: 着地隙発生F | K40: ベクトル | L40: KBG (R.E.) | M40: BKB (R.A.) | N40: FKB (R.F.) | O40: 盾削り値 | P40: ﾋｯﾄｽﾄｯﾌﾟ | Q40: ずらし | R40: 備考
A41: 空N | C41: 3-5 | D41: 45 | E41: 8 | F41: 9.6 | G41: 8.16 | H41: 4F | I41: {=INDEX('空中攻撃'!$O$3:$AB$109, MATCH($A$1,'空中攻撃'!$A$3:$A$109,0), MATCH(A41,'空中攻撃'!$O$2:$S$2,0))} -> 6 | J41: 3-38
B42: 持続 | C42: 6-27 | E42: 5 | F42: 6 | G42: 5.1 | H42: 3F
A43: 空前 | B43: 始 | C43: 16 | D43: 59 | E43: 12 | F43: 14.4 | G43: 12.24 | H43: 5F | I43: {=INDEX('空中攻撃'!$O$3:$AB$109, MATCH($A$1,'空中攻撃'!$A$3:$A$109,0), MATCH(A43,'空中攻撃'!$O$2:$S$2,0))} -> 17 | J43: 3-42
B44: メテオ | C44: 17-20 | E44: 14 | F44: 19.2 | G44: 16.32 | H44: 6F
B45: 持続 | C45: 21 | E45: 10 | F45: 12 | G45: 10.2 | H45: 4F
A46: 空後 | C46: 6-7 | D46: 33 | E46: 10.5 | F46: 12.6 | G46: 10.71 | H46: 4F | I46: {=INDEX('空中攻撃'!$O$3:$AB$109, MATCH($A$1,'空中攻撃'!$A$3:$A$109,0), MATCH(A46,'空中攻撃'!$O$2:$S$2,0))} -> 6 | J46: 6-18
B47: 持続 | C47: 8-10 | E47: 7 | F47: 8.4 | G47: 7.14 | H47: 3F
A48: 空上 | C48: 4-7 | D48: 30 | E48: 7 | F48: 8.4 | G48: 8.4 | H48: 3F | I48: {=INDEX('空中攻撃'!$O$3:$AA$109, MATCH($A$1,'空中攻撃'!$A$3:$A$109,0), MATCH(A48,'空中攻撃'!$O$2:$S$2,0))} -> 6 | J48: 2-16
A49: 空下 | B49: Hit 1-5 | C49: 5, 7, 9, 11, 13 | D49: 37 | E49: 1.4 | F49: 1.68 | G49: 1.428 | H49: 2F | I49: {=INDEX('空中攻撃'!$O$3:$AA$109, MATCH($A$1,'空中攻撃'!$A$3:$A$109,0), MATCH(A49,'空中攻撃'!$O$2:$S$2,0))} -> 15 | J49: 5-32
...

Sheet 2. ドンキーコング
A1: 2 | C1: =IMAGE(VLOOKUP($A$1,Fighters!A2:AI114,12,FALSE),1) -> #REF!
A2: =VLOOKUP($A$1,Fighters!$A$2:$AI$81,6,FALSE) -> #007d1e
A3: =VLOOKUP($A$1,Fighters!$A$2:$AI$81,14,FALSE) -> 2. ドンキーコング
A4: =VLOOKUP($A$1,Fighters!$A$2:$AI$81,13,FALSE) -> 1
I6: 最終更新
H8: 44543.226
A15: 行動フレーム・能力値
C16: 行動フレーム | E16: 能力値 | G16: 滞空フレーム | K16: ='テンプレート'!K16 -> 能力値その他
A17: ='テンプレート'!A17 -> ジャンプ回数 | B17: 2回 | C17: ='テンプレート'!C17 -> ジャンプ踏切 | D17: {=IF(INDEX('行動フレーム・能力値'!$C$2:$AD$115, MATCH($A$1,'行動フレーム・能力値'!$A$2:$A$115,0), MATCH(C17,'行動フレーム・能力値'!$C$1:$AD$1,0))="-", "-", INDEX('行動フレーム・能力値'!$C$2:$AD$115, MATCH($A$1,'行動フレーム・能力値'!$A$2:$A$115,0), MATCH(C17,'行動フレーム・能力値'!$C$1:$AD$1,0))&"F")} -> 3F | E17: ='テンプレート'!E17 -> 体重 | F17: {=IF(INDEX('行動フレーム・能力値'!$C$2:$AD$115, MATCH($A$1,'行動フレーム・能力値'!$A$2:$A$115,0), MATCH(E17,'行動フレーム・能力値'!$C$1:$AD$1,0))="-", "-", INDEX('行動フレーム・能力値'!$C$2:$AD$115, MATCH($A$1,'行動フレーム・能力値'!$A$2:$A$115,0), MATCH(E17,'行動フレーム・能力値'!$C$1:$AD$1,0))&" ["&INDEX('行動フレーム・能力値'!$C$2:$AD$115, MATCH($A$1,'行動フレーム・能力値'!$A$2:$A$115,0), MATCH(E17,'行動フレーム・能力値'!$C$1:$AD$1,0)-1)&IF(AND(INDEX('行動フレーム・能力値'!$C$2:$AD$115, MATCH($A$1,'行動フレーム・能力値'!$A$2:$A$115,0), MATCH(E17,'行動フレーム・能力値'!$C$1:$AD$1,0)-1)>=11, INDEX('行動フレーム・能力値'!$C$2:$AD$115, MATCH($A$1,'行動フレーム・能力値'!$A$2:$A$115,0), MATCH(E17,'行動フレーム・能力値'!$C$1:$AD$1,0)-1)<=13),"th",CHOOSE(MIN(5,RIGHT(INDEX('行動フレーム・能力値'!$C$2:$AD$115, MATCH($A$1,'行動フレーム・能力値'!$A$2:$A$115,0), MATCH(E17,'行動フレーム・能力値'!$C$1:$AD$1,0)-1))+1),"th","st","nd","rd","th"))&"]")} -> 127 [3rd] | G17: ='テンプレート'!G17 -> 小J滞空 | H17: {=IF(INDEX('行動フレーム・能力値'!$C$2:$AD$115, MATCH($A$1,'行動フレーム・能力値'!$A$2:$A$115,0), MATCH(G17,'行動フレーム・能力値'!$C$1:$AD$1,0))="-", "-", INDEX('行動フレーム・能力値'!$C$2:$AD$115, MATCH($A$1,'行動フレーム・能力値'!$A$2:$A$115,0), MATCH(G17,'行動フレーム・能力値'!$C$1:$AD$1,0))&"F")} -> 40F | K17: ='テンプレート'!K17 -> ダッシュ初速 | L17: {=IF(INDEX('能力値その他'!$C$2:$AD$115, MATCH($A$1,'能力値その他'!$A$2:$A$115,0), MATCH(K17,'能力値その他'!$C$1:$AD$1,0))="-", "-", INDEX('能力値その他'!$C$2:$AD$115, MATCH($A$1,'能力値その他'!$A$2:$A$115,0), MATCH(K17,'能力値その他'!$C$1:$AD$1,0))&" ["&INDEX('能力値その他'!$C$2:$AD$115, MATCH($A$1,'能力値その他'!$A$2:$A$115,0), MATCH(K17,'能力値その他'!$C$1:$AD$1,0)-1)&IF(AND(INDEX('能力値その他'!$C$2:$AD$115, MATCH($A$1,'能力値その他'!$A$2:$A$115,0), MATCH(K17,'能力値その他'!$C$1:$AD$1,0)-1)>=11, INDEX('能力値その他'!$C$2:$AD$115, MATCH($A$1,'能力値その他'!$A$2:$A$115,0), MATCH(K17,'能力値その他'!$C$1:$AD$1,0)-1)<=13),"th",CHOOSE(MIN(5,RIGHT(INDEX('能力値その他'!$C$2:$AD$115, MATCH($A$1,'能力値その他'!$A$2:$A$115,0), MATCH(K17,'能力値その他'!$C$1:$AD$1,0)-1))+1),"th","st","nd","rd","th"))&"]")} -> 2.09 [18th] | M17: ='テンプレート'!M17 -> 大J初速 | N17: {=IF(INDEX('能力値その他'!$C$2:$AD$115, MATCH($A$1,'能力値その他'!$A$2:$A$115,0), MATCH(M17,'能力値その他'!$C$1:$AD$1,0))="-", "-", INDEX('能力値その他'!$C$2:$AD$115, MATCH($A$1,'能力値その他'!$A$2:$A$115,0), MATCH(M17,'能力値その他'!$C$1:$AD$1,0))&" ["&INDEX('能力値その他'!$C$2:$AD$115, MATCH($A$1,'能力値その他'!$A$2:$A$115,0), MATCH(M17,'能力値その他'!$C$1:$AD$1,0)-1)&IF(AND(INDEX('能力値その他'!$C$2:$AD$115, MATCH($A$1,'能力値その他'!$A$2:$A$115,0), MATCH(M17,'能力値その他'!$C$1:$AD$1,0)-1)>=11, INDEX('能力値その他'!$C$2:$AD$115, MATCH($A$1,'能力値その他'!$A$2:$A$115,0), MATCH(M17,'能力値その他'!$C$1:$AD$1,0)-1)<=13),"th",CHOOSE(MIN(5,RIGHT(INDEX('能力値その他'!$C$2:$AD$115, MATCH($A$1,'能力値その他'!$A$2:$A$115,0), MATCH(M17,'能力値その他'!$C$1:$AD$1,0)-1))+1),"th","st","nd","rd","th"))&"]")} -> -
A18: ='テンプレート'!A18 -> しゃがみ歩き | B18: FALSE | C18: ='テンプレート'!C18 -> 小着地 | D18: {=IF(INDEX('行動フレーム・能力値'!$C$2:$AD$115, MATCH($A$1,'行動フレーム・能力値'!$A$2:$A$115,0), MATCH(C18,'行動フレーム・能力値'!$C$1:$AD$1,0))="-", "-", INDEX('行動フレーム・能力値'!$C$2:$AD$115, MATCH($A$1,'行動フレーム・能力値'!$A$2:$A$115,0), MATCH(C18,'行動フレーム・能力値'!$C$1:$AD$1,0))&"F")} -> 2F | E18: ='テンプレート'!E18 -> 歩行速度 | F18: {=IF(INDEX('行動フレーム・能力値'!$C$2:$AD$115, MATCH($A$1,'行動フレーム・能力値'!$A$2:$A$115,0), MATCH(E18,'行動フレーム・能力値'!$C$1:$AD$1,0))="-", "-", INDEX('行動フレーム・能力値'!$C$2:$AD$115, MATCH($A$1,'行動フレーム・能力値'!$A$2:$A$115,0), MATCH(E18,'行動フレーム・能力値'!$C$1:$AD$1,0))&" ["&INDEX('行動フレーム・能力値'!$C$2:$AD$115, MATCH($A$1,'行動フレーム・能力値'!$A$2:$A$115,0), MATCH(E18,'行動フレーム・能力値'!$C$1:$AD$1,0)-1)&IF(AND(INDEX('行動フレーム・能力値'!$C$2:$AD$115, MATCH($A$1,'行動フレーム・能力値'!$A$2:$A$115,0), MATCH(E18,'行動フレーム・能力値'!$C$1:$AD$1,0)-1)>=11, INDEX('行動フレーム・能力値'!$C$2:$AD$115, MATCH($A$1,'行動フレーム・能力値'!$A$2:$A$115,0), MATCH(E18,'行動フレーム・能力値'!$C$1:$AD$1,0)-1)<=13),"th",CHOOSE(MIN(5,RIGHT(INDEX('行動フレーム・能力値'!$C$2:$AD$115, MATCH($A$1,'行動フレーム・能力値'!$A$2:$A$115,0), MATCH(E18,'行動フレーム・能力値'!$C$1:$AD$1,0)-1))+1),"th","st","nd","rd","th"))&"]")} -> 1.365 [10th] | G18: ='テンプレート'!G18 -> 大J滞空 | H18: {=IF(INDEX('行動フレーム・能力値'!$C$2:$AD$115, MATCH($A$1,'行動フレーム・能力値'!$A$2:$A$115,0), MATCH(G18,'行動フレーム・能力値'!$C$1:$AD$1,0))="-", "-", INDEX('行動フレーム・能力値'!$C$2:$AD$115, MATCH($A$1,'行動フレーム・能力値'!$A$2:$A$115,0), MATCH(G18,'行動フレーム・能力値'!$C$1:$AD$1,0))&"F")} -> 53F | K18: ='テンプレート'!K18 -> 走行加速 | L18: {=IF(INDEX('能力値その他'!$C$2:$AD$115, MATCH($A$1,'能力値その他'!$A$2:$A$115,0), MATCH(K18,'能力値その他'!$C$1:$AD$1,0))="-", "-", INDEX('能力値その他'!$C$2:$AD$115, MATCH($A$1,'能力値その他'!$A$2:$A$115,0), MATCH(K18,'能力値その他'!$C$1:$AD$1,0))&" ["&INDEX('能力値その他'!$C$2:$AD$115, MATCH($A$1,'能力値その他'!$A$2:$A$115,0), MATCH(K18,'能力値その他'!$C$1:$AD$1,0)-1)&IF(AND(INDEX('能力値その他'!$C$2:$AD$115, MATCH($A$1,'能力値その他'!$A$2:$A$115,0), MATCH(K18,'能力値その他'!$C$1:$AD$1,0)-1)>=11, INDEX('能力値その他'!$C$2:$AD$115, MATCH($A$1,'能力値その他'!$A$2:$A$115,0), MATCH(K18,'能力値その他'!$C$1:$AD$1,0)-1)<=13),"th",CHOOSE(MIN(5,RIGHT(INDEX('能力値その他'!$C$2:$AD$115, MATCH($A$1,'能力値その他'!$A$2:$A$115,0), MATCH(K18,'能力値その他'!$C$1:$AD$1,0)-1))+1),"th","st","nd","rd","th"))&"]")} -> 0.11737 [73rd] | M18: ='テンプレート'!M18 -> 大J高度 | N18: {=IF(INDEX('能力値その他'!$C$2:$AD$115, MATCH($A$1,'能力値その他'!$A$2:$A$115,0), MATCH(M18,'能力値その他'!$C$1:$AD$1,0))="-", "-", INDEX('能力値その他'!$C$2:$AD$115, MATCH($A$1,'能力値その他'!$A$2:$A$115,0), MATCH(M18,'能力値その他'!$C$1:$AD$1,0))&" ["&INDEX('能力値その他'!$C$2:$AD$115, MATCH($A$1,'能力値その他'!$A$2:$A$115,0), MATCH(M18,'能力値その他'!$C$1:$AD$1,0)-1)&IF(AND(INDEX('能力値その他'!$C$2:$AD$115, MATCH($A$1,'能力値その他'!$A$2:$A$115,0), MATCH(M18,'能力値その他'!$C$1:$AD$1,0)-1)>=11, INDEX('能力値その他'!$C$2:$AD$115, MATCH($A$1,'能力値その他'!$A$2:$A$115,0), MATCH(M18,'能力値その他'!$C$1:$AD$1,0)-1)<=13),"th",CHOOSE(MIN(5,RIGHT(INDEX('能力値その他'!$C$2:$AD$115, MATCH($A$1,'能力値その他'!$A$2:$A$115,0), MATCH(M18,'能力値その他'!$C$1:$AD$1,0)-1))+1),"th","st","nd","rd","th"))&"]")} -> 34 [29th]
A19: ='テンプレート'!A19 -> カベジャンプ | B19: FALSE | C19: ='テンプレート'!C19 -> 大着地 | D19: {=IF(INDEX('行動フレーム・能力値'!$C$2:$AD$115, MATCH($A$1,'行動フレーム・能力値'!$A$2:$A$115,0), MATCH(C19,'行動フレーム・能力値'!$C$1:$AD$1,0))="-", "-", INDEX('行動フレーム・能力値'!$C$2:$AD$115, MATCH($A$1,'行動フレーム・能力値'!$A$2:$A$115,0), MATCH(C19,'行動フレーム・能力値'!$C$1:$AD$1,0))&"F")} -> 5F | E19: ='テンプレート'!E19 -> 走行速度 | F19: {=IF(INDEX('行動フレーム・能力値'!$C$2:$AD$115, MATCH($A$1,'行動フレーム・能力値'!$A$2:$A$115,0), MATCH(E19,'行動フレーム・能力値'!$C$1:$AD$1,0))="-", "-", INDEX('行動フレーム・能力値'!$C$2:$AD$115, MATCH($A$1,'行動フレーム・能力値'!$A$2:$A$115,0), MATCH(E19,'行動フレーム・能力値'!$C$1:$AD$1,0))&" ["&INDEX('行動フレーム・能力値'!$C$2:$AD$115, MATCH($A$1,'行動フレーム・能力値'!$A$2:$A$115,0), MATCH(E19,'行動フレーム・能力値'!$C$1:$AD$1,0)-1)&IF(AND(INDEX('行動フレーム・能力値'!$C$2:$AD$115, MATCH($A$1,'行動フレーム・能力値'!$A$2:$A$115,0), MATCH(E19,'行動フレーム・能力値'!$C$1:$AD$1,0)-1)>=11, INDEX('行動フレーム・能力値'!$C$2:$AD$115, MATCH($A$1,'行動フレーム・能力値'!$A$2:$A$115,0), MATCH(E19,'行動フレーム・能力値'!$C$1:$AD$1,0)-1)<=13),"th",CHOOSE(MIN(5,RIGHT(INDEX('行動フレーム・能力値'!$C$2:$AD$115, MATCH($A$1,'行動フレーム・能力値'!$A$2:$A$115,0), MATCH(E19,'行動フレーム・能力値'!$C$1:$AD$1,0)-1))+1),"th","st","nd","rd","th"))&"]")} -> 1.873 [29th] | G19: ='テンプレート'!G19 -> 小J急降下滞空 | H19: {=IF(INDEX('行動フレーム・能力値'!$C$2:$AD$115, MATCH($A$1,'行動フレーム・能力値'!$A$2:$A$115,0), MATCH(G19,'行動フレーム・能力値'!$C$1:$AD$1,0))="-", "-", INDEX('行動フレーム・能力値'!$C$2:$AD$115, MATCH($A$1,'行動フレーム・能力値'!$A$2:$A$115,0), MATCH(G19,'行動フレーム・能力値'!$C$1:$AD$1,0))&"F")} -> 27F | K19: ='テンプレート'!K19 -> 地上抵抗 | L19: {=IF(INDEX('能力値その他'!$C$2:$AD$115, MATCH($A$1,'能力値その他'!$A$2:$A$115,0), MATCH(K19,'能力値その他'!$C$1:$AD$1,0))="-", "-", INDEX('能力値その他'!$C$2:$AD$115, MATCH($A$1,'能力値その他'!$A$2:$A$115,0), MATCH(K19,'能力値その他'!$C$1:$AD$1,0))&" ["&INDEX('能力値その他'!$C$2:$AD$115, MATCH($A$1,'能力値その他'!$A$2:$A$115,0), MATCH(K19,'能力値その他'!$C$1:$AD$1,0)-1)&IF(AND(INDEX('能力値その他'!$C$2:$AD$115, MATCH($A$1,'能力値その他'!$A$2:$A$115,0), MATCH(K19,'能力値その他'!$C$1:$AD$1,0)-1)>=11, INDEX('能力値その他'!$C$2:$AD$115, MATCH($A$1,'能力値その他'!$A$2:$A$115,0), MATCH(K19,'能力値その他'!$C$1:$AD$1,0)-1)<=13),"th",CHOOSE(MIN(5,RIGHT(INDEX('能力値その他'!$C$2:$AD$115, MATCH($A$1,'能力値その他'!$A$2:$A$115,0), MATCH(K19,'能力値その他'!$C$1:$AD$1,0)-1))+1),"th","st","nd","rd","th"))&"]")} -> 0.123 [16th] | M19: ='テンプレート'!M19 -> 小J高度 | N19: {=IF(INDEX('能力値その他'!$C$2:$AD$115, MATCH($A$1,'能力値その他'!$A$2:$A$115,0), MATCH(M19,'能力値その他'!$C$1:$AD$1,0))="-", "-", INDEX('能力値その他'!$C$2:$AD$115, MATCH($A$1,'能力値その他'!$A$2:$A$115,0), MATCH(M19,'能力値その他'!$C$1:$AD$1,0))&" ["&INDEX('能力値その他'!$C$2:$AD$115, MATCH($A$1,'能力値その他'!$A$2:$A$115,0), MATCH(M19,'能力値その他'!$C$1:$AD$1,0)-1)&IF(AND(INDEX('能力値その他'!$C$2:$AD$115, MATCH($A$1,'能力値その他'!$A$2:$A$115,0), MATCH(M19,'能力値その他'!$C$1:$AD$1,0)-1)>=11, INDEX('能力値その他'!$C$2:$AD$115, MATCH($A$1,'能力値その他'!$A$2:$A$115,0), MATCH(M19,'能力値その他'!$C$1:$AD$1,0)-1)<=13),"th",CHOOSE(MIN(5,RIGHT(INDEX('能力値その他'!$C$2:$AD$115, MATCH($A$1,'能力値その他'!$A$2:$A$115,0), MATCH(M19,'能力値その他'!$C$1:$AD$1,0)-1))+1),"th","st","nd","rd","th"))&"]")} -> 17.3 [22nd]
A20: ='テンプレート'!A20 -> カベ張りつき | B20: FALSE | C20: 走行移行前F | D20: {=IF(INDEX('行動フレーム・能力値'!$C$2:$AD$115, MATCH($A$1,'行動フレーム・能力値'!$A$2:$A$115,0), MATCH(C20,'行動フレーム・能力値'!$C$1:$AD$1,0))="-", "-", INDEX('行動フレーム・能力値'!$C$2:$AD$115, MATCH($A$1,'行動フレーム・能力値'!$A$2:$A$115,0), MATCH(C20,'行動フレーム・能力値'!$C$1:$AD$1,0))&"F ["&INDEX('行動フレーム・能力値'!$C$2:$AD$115, MATCH($A$1,'行動フレーム・能力値'!$A$2:$A$115,0), MATCH(C20,'行動フレーム・能力値'!$C$1:$AD$1,0)-1)&IF(AND(INDEX('行動フレーム・能力値'!$C$2:$AD$115, MATCH($A$1,'行動フレーム・能力値'!$A$2:$A$115,0), MATCH(C20,'行動フレーム・能力値'!$C$1:$AD$1,0)-1)>=11, INDEX('行動フレーム・能力値'!$C$2:$AD$115, MATCH($A$1,'行動フレーム・能力値'!$A$2:$A$115,0), MATCH(C20,'行動フレーム・能力値'!$C$1:$AD$1,0)-1)<=13),"th",CHOOSE(MIN(5,RIGHT(INDEX('行動フレーム・能力値'!$C$2:$AD$115, MATCH($A$1,'行動フレーム・能力値'!$A$2:$A$115,0), MATCH(C20,'行動フレーム・能力値'!$C$1:$AD$1,0)-1))+1),"th","st","nd","rd","th"))&"]")} -> 15F [80th] | E20: ='テンプレート'!E20 -> 空中速度 | F20: {=IF(INDEX('行動フレーム・能力値'!$C$2:$AD$115, MATCH($A$1,'行動フレーム・能力値'!$A$2:$A$115,0), MATCH(E20,'行動フレーム・能力値'!$C$1:$AD$1,0))="-", "-", INDEX('行動フレーム・能力値'!$C$2:$AD$115, MATCH($A$1,'行動フレーム・能力値'!$A$2:$A$115,0), MATCH(E20,'行動フレーム・能力値'!$C$1:$AD$1,0))&" ["&INDEX('行動フレーム・能力値'!$C$2:$AD$115, MATCH($A$1,'行動フレーム・能力値'!$A$2:$A$115,0), MATCH(E20,'行動フレーム・能力値'!$C$1:$AD$1,0)-1)&IF(AND(INDEX('行動フレーム・能力値'!$C$2:$AD$115, MATCH($A$1,'行動フレーム・能力値'!$A$2:$A$115,0), MATCH(E20,'行動フレーム・能力値'!$C$1:$AD$1,0)-1)>=11, INDEX('行動フレーム・能力値'!$C$2:$AD$115, MATCH($A$1,'行動フレーム・能力値'!$A$2:$A$115,0), MATCH(E20,'行動フレーム・能力値'!$C$1:$AD$1,0)-1)<=13),"th",CHOOSE(MIN(5,RIGHT(INDEX('行動フレーム・能力値'!$C$2:$AD$115, MATCH($A$1,'行動フレーム・能力値'!$A$2:$A$115,0), MATCH(E20,'行動フレーム・能力値'!$C$1:$AD$1,0)-1))+1),"th","st","nd","rd","th"))&"]")} -> 1.208 [13th] | G20: ='テンプレート'!G20 -> 大J急降下滞空 | H20: {=IF(INDEX('行動フレーム・能力値'!$C$2:$AD$115, MATCH($A$1,'行動フレーム・能力値'!$A$2:$A$115,0), MATCH(G20,'行動フレーム・能力値'!$C$1:$AD$1,0))="-", "-", INDEX('行動フレーム・能力値'!$C$2:$AD$115, MATCH($A$1,'行動フレーム・能力値'!$A$2:$A$115,0), MATCH(G20,'行動フレーム・能力値'!$C$1:$AD$1,0))&"F")} -> 37F | K20: ='テンプレート'!K20 -> 空中加速 | L20: {=IF(INDEX('能力値その他'!$C$2:$AD$115, MATCH($A$1,'能力値その他'!$A$2:$A$115,0), MATCH(K20,'能力値その他'!$C$1:$AD$1,0))="-", "-", INDEX('能力値その他'!$C$2:$AD$115, MATCH($A$1,'能力値その他'!$A$2:$A$115,0), MATCH(K20,'能力値その他'!$C$1:$AD$1,0))&" ["&INDEX('能力値その他'!$C$2:$AD$115, MATCH($A$1,'能力値その他'!$A$2:$A$115,0), MATCH(K20,'能力値その他'!$C$1:$AD$1,0)-1)&IF(AND(INDEX('能力値その他'!$C$2:$AD$115, MATCH($A$1,'能力値その他'!$A$2:$A$115,0), MATCH(K20,'能力値その他'!$C$1:$AD$1,0)-1)>=11, INDEX('能力値その他'!$C$2:$AD$115, MATCH($A$1,'能力値その他'!$A$2:$A$115,0), MATCH(K20,'能力値その他'!$C$1:$AD$1,0)-1)<=13),"th",CHOOSE(MIN(5,RIGHT(INDEX('能力値その他'!$C$2:$AD$115, MATCH($A$1,'能力値その他'!$A$2:$A$115,0), MATCH(K20,'能力値その他'!$C$1:$AD$1,0)-1))+1),"th","st","nd","rd","th"))&"]")} -> 0.06 [58th] | M20: ='テンプレート'!M20 -> 空中J高度 | N20: {=IF(INDEX('能力値その他'!$C$2:$AD$115, MATCH($A$1,'能力値その他'!$A$2:$A$115,0), MATCH(M20,'能力値その他'!$C$1:$AD$1,0))="-", "-", INDEX('能力値その他'!$C$2:$AD$115, MATCH($A$1,'能力値その他'!$A$2:$A$115,0), MATCH(M20,'能力値その他'!$C$1:$AD$1,0))&" ["&INDEX('能力値その他'!$C$2:$AD$115, MATCH($A$1,'能力値その他'!$A$2:$A$115,0), MATCH(M20,'能力値その他'!$C$1:$AD$1,0)-1)&IF(AND(INDEX('能力値その他'!$C$2:$AD$115, MATCH($A$1,'能力値その他'!$A$2:$A$115,0), MATCH(M20,'能力値その他'!$C$1:$AD$1,0)-1)>=11, INDEX('能力値その他'!$C$2:$AD$115, MATCH($A$1,'能力値その他'!$A$2:$A$115,0), MATCH(M20,'能力値その他'!$C$1:$AD$1,0)-1)<=13),"th",CHOOSE(MIN(5,RIGHT(INDEX('能力値その他'!$C$2:$AD$115, MATCH($A$1,'能力値その他'!$A$2:$A$115,0), MATCH(M20,'能力値その他'!$C$1:$AD$1,0)-1))+1),"th","st","nd","rd","th"))&"]")} -> 35.5 [27th]
A21: ='テンプレート'!A21 -> 空中ワイヤー | B21: FALSE | C21: ='テンプレート'!C21 -> ステップ全体F | D21: {=IF(INDEX('行動フレーム・能力値'!$C$2:$AD$115, MATCH($A$1,'行動フレーム・能力値'!$A$2:$A$115,0), MATCH(C21,'行動フレーム・能力値'!$C$1:$AD$1,0))="-", "-", INDEX('行動フレーム・能力値'!$C$2:$AD$115, MATCH($A$1,'行動フレーム・能力値'!$A$2:$A$115,0), MATCH(C21,'行動フレーム・能力値'!$C$1:$AD$1,0))&"F ["&INDEX('行動フレーム・能力値'!$C$2:$AD$115, MATCH($A$1,'行動フレーム・能力値'!$A$2:$A$115,0), MATCH(C21,'行動フレーム・能力値'!$C$1:$AD$1,0)-1)&IF(AND(INDEX('行動フレーム・能力値'!$C$2:$AD$115, MATCH($A$1,'行動フレーム・能力値'!$A$2:$A$115,0), MATCH(C21,'行動フレーム・能力値'!$C$1:$AD$1,0)-1)>=11, INDEX('行動フレーム・能力値'!$C$2:$AD$115, MATCH($A$1,'行動フレーム・能力値'!$A$2:$A$115,0), MATCH(C21,'行動フレーム・能力値'!$C$1:$AD$1,0)-1)<=13),"th",CHOOSE(MIN(5,RIGHT(INDEX('行動フレーム・能力値'!$C$2:$AD$115, MATCH($A$1,'行動フレーム・能力値'!$A$2:$A$115,0), MATCH(C21,'行動フレーム・能力値'!$C$1:$AD$1,0)-1))+1),"th","st","nd","rd","th"))&"]")} -> 19F [13th] | E21: ='テンプレート'!E21 -> 落下速度 | F21: {=IF(INDEX('行動フレーム・能力値'!$C$2:$AD$115, MATCH($A$1,'行動フレーム・能力値'!$A$2:$A$115,0), MATCH(E21,'行動フレーム・能力値'!$C$1:$AD$1,0))="-", "-", INDEX('行動フレーム・能力値'!$C$2:$AD$115, MATCH($A$1,'行動フレーム・能力値'!$A$2:$A$115,0), MATCH(E21,'行動フレーム・能力値'!$C$1:$AD$1,0))&" ["&INDEX('行動フレーム・能力値'!$C$2:$AD$115, MATCH($A$1,'行動フレーム・能力値'!$A$2:$A$115,0), MATCH(E21,'行動フレーム・能力値'!$C$1:$AD$1,0)-1)&IF(AND(INDEX('行動フレーム・能力値'!$C$2:$AD$115, MATCH($A$1,'行動フレーム・能力値'!$A$2:$A$115,0), MATCH(E21,'行動フレーム・能力値'!$C$1:$AD$1,0)-1)>=11, INDEX('行動フレーム・能力値'!$C$2:$AD$115, MATCH($A$1,'行動フレーム・能力値'!$A$2:$A$115,0), MATCH(E21,'行動フレーム・能力値'!$C$1:$AD$1,0)-1)<=13),"th",CHOOSE(MIN(5,RIGHT(INDEX('行動フレーム・能力値'!$C$2:$AD$115, MATCH($A$1,'行動フレーム・能力値'!$A$2:$A$115,0), MATCH(E21,'行動フレーム・能力値'!$C$1:$AD$1,0)-1))+1),"th","st","nd","rd","th"))&"]")} -> 1.63 [39th] | K21: ='テンプレート'!K21 -> 空中抵抗 | L21: {=IF(INDEX('能力値その他'!$C$2:$AD$115, MATCH($A$1,'能力値その他'!$A$2:$A$115,0), MATCH(K21,'能力値その他'!$C$1:$AD$1,0))="-", "-", INDEX('能力値その他'!$C$2:$AD$115, MATCH($A$1,'能力値その他'!$A$2:$A$115,0), MATCH(K21,'能力値その他'!$C$1:$AD$1,0))&" ["&INDEX('能力値その他'!$C$2:$AD$115, MATCH($A$1,'能力値その他'!$A$2:$A$115,0), MATCH(K21,'能力値その他'!$C$1:$AD$1,0)-1)&IF(AND(INDEX('能力値その他'!$C$2:$AD$115, MATCH($A$1,'能力値その他'!$A$2:$A$115,0), MATCH(K21,'能力値その他'!$C$1:$AD$1,0)-1)>=11, INDEX('能力値その他'!$C$2:$AD$115, MATCH($A$1,'能力値その他'!$A$2:$A$115,0), MATCH(K21,'能力値その他'!$C$1:$AD$1,0)-1)<=13),"th",CHOOSE(MIN(5,RIGHT(INDEX('能力値その他'!$C$2:$AD$115, MATCH($A$1,'能力値その他'!$A$2:$A$115,0), MATCH(K21,'能力値その他'!$C$1:$AD$1,0)-1))+1),"th","st","nd","rd","th"))&"]")} -> 0.015 [9th]
E22: ='テンプレート'!E22 -> 急降下速度 | F22: {=IF(INDEX('行動フレーム・能力値'!$C$2:$AD$115, MATCH($A$1,'行動フレーム・能力値'!$A$2:$A$115,0), MATCH(E22,'行動フレーム・能力値'!$C$1:$AD$1,0))="-", "-", INDEX('行動フレーム・能力値'!$C$2:$AD$115, MATCH($A$1,'行動フレーム・能力値'!$A$2:$A$115,0), MATCH(E22,'行動フレーム・能力値'!$C$1:$AD$1,0))&" ["&INDEX('行動フレーム・能力値'!$C$2:$AD$115, MATCH($A$1,'行動フレーム・能力値'!$A$2:$A$115,0), MATCH(E22,'行動フレーム・能力値'!$C$1:$AD$1,0)-1)&IF(AND(INDEX('行動フレーム・能力値'!$C$2:$AD$115, MATCH($A$1,'行動フレーム・能力値'!$A$2:$A$115,0), MATCH(E22,'行動フレーム・能力値'!$C$1:$AD$1,0)-1)>=11, INDEX('行動フレーム・能力値'!$C$2:$AD$115, MATCH($A$1,'行動フレーム・能力値'!$A$2:$A$115,0), MATCH(E22,'行動フレーム・能力値'!$C$1:$AD$1,0)-1)<=13),"th",CHOOSE(MIN(5,RIGHT(INDEX('行動フレーム・能力値'!$C$2:$AD$115, MATCH($A$1,'行動フレーム・能力値'!$A$2:$A$115,0), MATCH(E22,'行動フレーム・能力値'!$C$1:$AD$1,0)-1))+1),"th","st","nd","rd","th"))&"]")} -> 2.608 [40th] | K22: ='テンプレート'!K22 -> 重力 | L22: {=IF(INDEX('能力値その他'!$C$2:$AD$115, MATCH($A$1,'能力値その他'!$A$2:$A$115,0), MATCH(K22,'能力値その他'!$C$1:$AD$1,0))="-", "-", INDEX('能力値その他'!$C$2:$AD$115, MATCH($A$1,'能力値その他'!$A$2:$A$115,0), MATCH(K22,'能力値その他'!$C$1:$AD$1,0))&" ["&INDEX('能力値その他'!$C$2:$AD$115, MATCH($A$1,'能力値その他'!$A$2:$A$115,0), MATCH(K22,'能力値その他'!$C$1:$AD$1,0)-1)&IF(AND(INDEX('能力値その他'!$C$2:$AD$115, MATCH($A$1,'能力値その他'!$A$2:$A$115,0), MATCH(K22,'能力値その他'!$C$1:$AD$1,0)-1)>=11, INDEX('能力値その他'!$C$2:$AD$115, MATCH($A$1,'能力値その他'!$A$2:$A$115,0), MATCH(K22,'能力値その他'!$C$1:$AD$1,0)-1)<=13),"th",CHOOSE(MIN(5,RIGHT(INDEX('能力値その他'!$C$2:$AD$115, MATCH($A$1,'能力値その他'!$A$2:$A$115,0), MATCH(K22,'能力値その他'!$C$1:$AD$1,0)-1))+1),"th","st","nd","rd","th"))&"]")} -> 0.085 [57th]
A24: 地上攻撃
C25: 判定持続 | D25: 全体フレーム | E25: 基礎ダメージ | F25: ダメージ (1v1) | G25: ガード硬直 | H25: 備考 | K25: ='テンプレート'!K25 -> ベクトル | L25: ='テンプレート'!L25 -> KBG (R.E.) | M25: ='テンプレート'!M25 -> BKB (R.A.) | N25: ='テンプレート'!N25 -> FKB (R.F.) | O25: ='テンプレート'!O25 -> 盾削り値 | P25: ='テンプレート'!P25 -> ﾋｯﾄｽﾄｯﾌﾟ | Q25: ='テンプレート'!Q25 -> ずらし | U25: 慣性消去
A26: 弱攻撃 | B26: 弱1 | C26: 5-6 | D26: 24 | E26: 4 | F26: 4.8 | G26: 5F | H26: 8-28Fは弱2に移行可能。 | U26: なし
B27: 弱2 | C27: 4-6 | D27: 31 | E27: 6 | F27: 7.2 | G27: 6F | U27: 1F
A28: ダッシュ攻撃 | C28: 9-12 | D28: 34 | E28: 12 | F28: 14.4 | G28: 11F | U28: 1F
B29: 持続 | C29: 13-24 | E29: 9 | F29: 10.8 | G29: 9F
A30: 横強 | B30: 上シフト | C30: 7-9 | D30: 35 | E30: 9 | F30: 10.8 | G30: 9F | H30: 左腕無敵：6-9F (全シフト) 転倒率：+15% (下シフトのみ) | U30: 1F(*)
B31: 無シフト | D31: 34 | E31: 8 | F31: 9.6 | G31: 8F
B32: 下シフト | D32: 35 | E32: 9 | F32: 10.8 | G32: 9F
A33: 上強 | C33: 5-11 | D33: 38 | E33: 8/9/10 | F33: 9.6/10.8/12 | G33: 8F/9F/10F | H33: 右腕無敵：5-11F | U33: なし
A34: 下強 | C34: 6-7 | D34: 24 | E34: 6 | F34: 7.2 | G34: 6F | H34: 左腕無敵：5-7F 転倒率：+40% | U34: なし
A35: 横スマッシュ | C35: 22-23 | D35: 54 | E35: 22/21 | F35: 26.4/25.2 | G35: 14F/14F | H35: 頭・両腕無敵：20-26F 相殺モーションなし。 溜め開始：15F目 | U35: 16F
A36: 上スマッシュ | C36: 14-15 | D36: 49 | E36: 19 | F36: 22.8 | G36: 13F | H36: 頭・両腕無敵：12-15F 相殺モーションなし。 溜め開始：7F目 | U36: なし
A37: 下スマッシュ | B37: 始 | C37: 11-12 | D37: 55 | E37: 17/17/14/14 | F37: 20.4/20.4/16.8/16.8 | G37: 11F/11F/10F/10F | H37: 両腕無敵：11-14F 相殺モーションなし。 溜め開始：3F目 | U37: なし
C38: 13-14 | E38: 18/18/14/14 | F38: 21.6/21.6/16.8/16.8 | G38: 12F/12F/10F/10F
A40: 空中攻撃
C41: 判定持続 | D41: 全体フレーム | E41: 基礎ダメージ | F41: ダメージ (1v1) | G41: ダメ (1v1+小J) | H41: ガード硬直 | I41: ='テンプレート'!I56 -> 着地隙 | J41: 着地隙発生F | K41: ='テンプレート'!K56 -> ベクトル | L41: ='テンプレート'!L56 -> KBG (R.E.) | M41: ='テンプレート'!M56 -> BKB (R.A.) | N41: ='テンプレート'!N56 -> FKB (R.F.) | O41: ='テンプレート'!O56 -> 盾削り値 | P41: ='テンプレート'!P56 -> ﾋｯﾄｽﾄｯﾌﾟ | Q41: ='テンプレート'!Q56 -> ずらし | R41: ='テンプレート'!R56 -> 備考
A42: 空N | C42: 10-13 | D42: 38 | E42: 12 | F42: 14.4 | G42: 12.24 | H42: 5F | I42: {=INDEX('空中攻撃'!$O$3:$AB$109, MATCH($A$1,'空中攻撃'!$A$3:$A$109,0), MATCH(A42,'空中攻撃'!$O$2:$S$2,0))} -> 10 | J42: 10-26
B43: 持続 | C43: 14-26 | E43: 9 | F43: 10.8 | G43: 9.18 | H43: 4F
A44: 空前 | C44: 18-20 | D44: 55 | E44: 16 | F44: 19.2 | G44: 16.32 | H44: 6F | I44: {=INDEX('空中攻撃'!$O$3:$AB$109, MATCH($A$1,'空中攻撃'!$A$3:$A$109,0), MATCH(A44,'空中攻撃'!$O$2:$S$2,0))} -> 17 | J44: 1-55
B45: 持続 | C45: 21-23 | E45: 15/13 | F45: 18/15.6 | G45: 15.3/13.26 | H45: 5F/5F
A46: 空後 | C46: 7-8 | D46: 31 | E46: 13 | F46: 15.6 | G46: 13.26 | H46: 5F | I46: {=INDEX('空中攻撃'!$O$3:$AA$109, MATCH($A$1,'空中攻撃'!$A$3:$A$109,0), MATCH(A46,'空中攻撃'!$O$2:$S$2,0))} -> 11 | J46: 7-30
B47: 持続 | C47: 9-16 | E47: 8 | F47: 9.6 | G47: 8.16 | H47: 4F
A48: 空上 | C48: 6-10 | D48: 37 | E48: 13 | F48: 15.6 | G48: 13.26 | H48: 5F | I48: {=INDEX('空中攻撃'!$O$3:$AA$109, MATCH($A$1,'空中攻撃'!$A$3:$A$109,0), MATCH(A48,'空中攻撃'!$O$2:$S$2,0))} -> 15 | J48: 6-25 | R48: 頭無敵：5-10F
A49: 空下 | C49: 14-16 | D49: 54 | E49: 16/13 | F49: 19.2/15.6 | G49: 16.32/13.26 | H49: 6F/5F | I49: {=INDEX('空中攻撃'!$O$3:$AA$109, MATCH($A$1,'空中攻撃'!$A$3:$A$109,0), MATCH(A49,'空中攻撃'!$O$2:$S$2,0))} -> 14 | J49: 3-49
A51: 必殺ワザ
...

Sheet 3. リンク
A1: 3 | C1: =IMAGE(VLOOKUP($A$1,Fighters!A2:AI114,12,FALSE),1) -> #REF!
A2: =VLOOKUP($A$1,Fighters!$A$2:$AI$81,6,FALSE) -> #5bb8d4
A3: =VLOOKUP($A$1,Fighters!$A$2:$AI$81,14,FALSE) -> 3. リンク
A4: =VLOOKUP($A$1,Fighters!$A$2:$AI$81,13,FALSE) -> 1
I6: 最終更新
H8: 44533.408
A15: ='テンプレート'!A15 -> 行動フレーム・能力値
C16: ='テンプレート'!C16 -> 行動フレーム | E16: ='テンプレート'!E16 -> 能力値 | G16: ='テンプレート'!G16 -> 滞空フレーム | K16: ='テンプレート'!K16 -> 能力値その他
A17: ='テンプレート'!A17 -> ジャンプ回数 | B17: 2回 | C17: ='テンプレート'!C17 -> ジャンプ踏切 | D17: {=IF(INDEX('行動フレーム・能力値'!$C$2:$AD$115, MATCH($A$1,'行動フレーム・能力値'!$A$2:$A$115,0), MATCH(C17,'行動フレーム・能力値'!$C$1:$AD$1,0))="-", "-", INDEX('行動フレーム・能力値'!$C$2:$AD$115, MATCH($A$1,'行動フレーム・能力値'!$A$2:$A$115,0), MATCH(C17,'行動フレーム・能力値'!$C$1:$AD$1,0))&"F")} -> 3F | E17: ='テンプレート'!E17 -> 体重 | F17: {=IF(INDEX('行動フレーム・能力値'!$C$2:$AD$115, MATCH($A$1,'行動フレーム・能力値'!$A$2:$A$115,0), MATCH(E17,'行動フレーム・能力値'!$C$1:$AD$1,0))="-", "-", INDEX('行動フレーム・能力値'!$C$2:$AD$115, MATCH($A$1,'行動フレーム・能力値'!$A$2:$A$115,0), MATCH(E17,'行動フレーム・能力値'!$C$1:$AD$1,0))&" ["&INDEX('行動フレーム・能力値'!$C$2:$AD$115, MATCH($A$1,'行動フレーム・能力値'!$A$2:$A$115,0), MATCH(E17,'行動フレーム・能力値'!$C$1:$AD$1,0)-1)&IF(AND(INDEX('行動フレーム・能力値'!$C$2:$AD$115, MATCH($A$1,'行動フレーム・能力値'!$A$2:$A$115,0), MATCH(E17,'行動フレーム・能力値'!$C$1:$AD$1,0)-1)>=11, INDEX('行動フレーム・能力値'!$C$2:$AD$115, MATCH($A$1,'行動フレーム・能力値'!$A$2:$A$115,0), MATCH(E17,'行動フレーム・能力値'!$C$1:$AD$1,0)-1)<=13),"th",CHOOSE(MIN(5,RIGHT(INDEX('行動フレーム・能力値'!$C$2:$AD$115, MATCH($A$1,'行動フレーム・能力値'!$A$2:$A$115,0), MATCH(E17,'行動フレーム・能力値'!$C$1:$AD$1,0)-1))+1),"th","st","nd","rd","th"))&"]")} -> 104 [22nd] | G17: ='テンプレート'!G17 -> 小J滞空 | H17: {=IF(INDEX('行動フレーム・能力値'!$C$2:$AD$115, MATCH($A$1,'行動フレーム・能力値'!$A$2:$A$115,0), MATCH(G17,'行動フレーム・能力値'!$C$1:$AD$1,0))="-", "-", INDEX('行動フレーム・能力値'!$C$2:$AD$115, MATCH($A$1,'行動フレーム・能力値'!$A$2:$A$115,0), MATCH(G17,'行動フレーム・能力値'!$C$1:$AD$1,0))&"F")} -> 33F | K17: ='テンプレート'!K17 -> ダッシュ初速 | L17: {=IF(INDEX('能力値その他'!$C$2:$AD$115, MATCH($A$1,'能力値その他'!$A$2:$A$115,0), MATCH(K17,'能力値その他'!$C$1:$AD$1,0))="-", "-", INDEX('能力値その他'!$C$2:$AD$115, MATCH($A$1,'能力値その他'!$A$2:$A$115,0), MATCH(K17,'能力値その他'!$C$1:$AD$1,0))&" ["&INDEX('能力値その他'!$C$2:$AD$115, MATCH($A$1,'能力値その他'!$A$2:$A$115,0), MATCH(K17,'能力値その他'!$C$1:$AD$1,0)-1)&IF(AND(INDEX('能力値その他'!$C$2:$AD$115, MATCH($A$1,'能力値その他'!$A$2:$A$115,0), MATCH(K17,'能力値その他'!$C$1:$AD$1,0)-1)>=11, INDEX('能力値その他'!$C$2:$AD$115, MATCH($A$1,'能力値その他'!$A$2:$A$115,0), MATCH(K17,'能力値その他'!$C$1:$AD$1,0)-1)<=13),"th",CHOOSE(MIN(5,RIGHT(INDEX('能力値その他'!$C$2:$AD$115, MATCH($A$1,'能力値その他'!$A$2:$A$115,0), MATCH(K17,'能力値その他'!$C$1:$AD$1,0)-1))+1),"th","st","nd","rd","th"))&"]")} -> 1.98 [30th] | M17: ='テンプレート'!M17 -> 大J初速 | N17: {=IF(INDEX('能力値その他'!$C$2:$AD$115, MATCH($A$1,'能力値その他'!$A$2:$A$115,0), MATCH(M17,'能力値その他'!$C$1:$AD$1,0))="-", "-", INDEX('能力値その他'!$C$2:$AD$115, MATCH($A$1,'能力値その他'!$A$2:$A$115,0), MATCH(M17,'能力値その他'!$C$1:$AD$1,0))&" ["&INDEX('能力値その他'!$C$2:$AD$115, MATCH($A$1,'能力値その他'!$A$2:$A$115,0), MATCH(M17,'能力値その他'!$C$1:$AD$1,0)-1)&IF(AND(INDEX('能力値その他'!$C$2:$AD$115, MATCH($A$1,'能力値その他'!$A$2:$A$115,0), MATCH(M17,'能力値その他'!$C$1:$AD$1,0)-1)>=11, INDEX('能力値その他'!$C$2:$AD$115, MATCH($A$1,'能力値その他'!$A$2:$A$115,0), MATCH(M17,'能力値その他'!$C$1:$AD$1,0)-1)<=13),"th",CHOOSE(MIN(5,RIGHT(INDEX('能力値その他'!$C$2:$AD$115, MATCH($A$1,'能力値その他'!$A$2:$A$115,0), MATCH(M17,'能力値その他'!$C$1:$AD$1,0)-1))+1),"th","st","nd","rd","th"))&"]")} -> -
A18: ='テンプレート'!A18 -> しゃがみ歩き | B18: FALSE | C18: ='テンプレート'!C18 -> 小着地 | D18: {=IF(INDEX('行動フレーム・能力値'!$C$2:$AD$115, MATCH($A$1,'行動フレーム・能力値'!$A$2:$A$115,0), MATCH(C18,'行動フレーム・能力値'!$C$1:$AD$1,0))="-", "-", INDEX('行動フレーム・能力値'!$C$2:$AD$115, MATCH($A$1,'行動フレーム・能力値'!$A$2:$A$115,0), MATCH(C18,'行動フレーム・能力値'!$C$1:$AD$1,0))&"F")} -> 2F | E18: ='テンプレート'!E18 -> 歩行速度 | F18: {=IF(INDEX('行動フレーム・能力値'!$C$2:$AD$115, MATCH($A$1,'行動フレーム・能力値'!$A$2:$A$115,0), MATCH(E18,'行動フレーム・能力値'!$C$1:$AD$1,0))="-", "-", INDEX('行動フレーム・能力値'!$C$2:$AD$115, MATCH($A$1,'行動フレーム・能力値'!$A$2:$A$115,0), MATCH(E18,'行動フレーム・能力値'!$C$1:$AD$1,0))&" ["&INDEX('行動フレーム・能力値'!$C$2:$AD$115, MATCH($A$1,'行動フレーム・能力値'!$A$2:$A$115,0), MATCH(E18,'行動フレーム・能力値'!$C$1:$AD$1,0)-1)&IF(AND(INDEX('行動フレーム・能力値'!$C$2:$AD$115, MATCH($A$1,'行動フレーム・能力値'!$A$2:$A$115,0), MATCH(E18,'行動フレーム・能力値'!$C$1:$AD$1,0)-1)>=11, INDEX('行動フレーム・能力値'!$C$2:$AD$115, MATCH($A$1,'行動フレーム・能力値'!$A$2:$A$115,0), MATCH(E18,'行動フレーム・能力値'!$C$1:$AD$1,0)-1)<=13),"th",CHOOSE(MIN(5,RIGHT(INDEX('行動フレーム・能力値'!$C$2:$AD$115, MATCH($A$1,'行動フレーム・能力値'!$A$2:$A$115,0), MATCH(E18,'行動フレーム・能力値'!$C$1:$AD$1,0)-1))+1),"th","st","nd","rd","th"))&"]")} -> 1.247 [23rd] | G18: ='テンプレート'!G18 -> 大J滞空 | H18: {=IF(INDEX('行動フレーム・能力値'!$C$2:$AD$115, MATCH($A$1,'行動フレーム・能力値'!$A$2:$A$115,0), MATCH(G18,'行動フレーム・能力値'!$C$1:$AD$1,0))="-", "-", INDEX('行動フレーム・能力値'!$C$2:$AD$115, MATCH($A$1,'行動フレーム・能力値'!$A$2:$A$115,0), MATCH(G18,'行動フレーム・能力値'!$C$1:$AD$1,0))&"F")} -> 45F | K18: ='テンプレート'!K18 -> 走行加速 | L18: {=IF(INDEX('能力値その他'!$C$2:$AD$115, MATCH($A$1,'能力値その他'!$A$2:$A$115,0), MATCH(K18,'能力値その他'!$C$1:$AD$1,0))="-", "-", INDEX('能力値その他'!$C$2:$AD$115, MATCH($A$1,'能力値その他'!$A$2:$A$115,0), MATCH(K18,'能力値その他'!$C$1:$AD$1,0))&" ["&INDEX('能力値その他'!$C$2:$AD$115, MATCH($A$1,'能力値その他'!$A$2:$A$115,0), MATCH(K18,'能力値その他'!$C$1:$AD$1,0)-1)&IF(AND(INDEX('能力値その他'!$C$2:$AD$115, MATCH($A$1,'能力値その他'!$A$2:$A$115,0), MATCH(K18,'能力値その他'!$C$1:$AD$1,0)-1)>=11, INDEX('能力値その他'!$C$2:$AD$115, MATCH($A$1,'能力値その他'!$A$2:$A$115,0), MATCH(K18,'能力値その他'!$C$1:$AD$1,0)-1)<=13),"th",CHOOSE(MIN(5,RIGHT(INDEX('能力値その他'!$C$2:$AD$115, MATCH($A$1,'能力値その他'!$A$2:$A$115,0), MATCH(K18,'能力値その他'!$C$1:$AD$1,0)-1))+1),"th","st","nd","rd","th"))&"]")} -> 0.17567 [11th] | M18: ='テンプレート'!M18 -> 大J高度 | N18: {=IF(INDEX('能力値その他'!$C$2:$AD$115, MATCH($A$1,'能力値その他'!$A$2:$A$115,0), MATCH(M18,'能力値その他'!$C$1:$AD$1,0))="-", "-", INDEX('能力値その他'!$C$2:$AD$115, MATCH($A$1,'能力値その他'!$A$2:$A$115,0), MATCH(M18,'能力値その他'!$C$1:$AD$1,0))&" ["&INDEX('能力値その他'!$C$2:$AD$115, MATCH($A$1,'能力値その他'!$A$2:$A$115,0), MATCH(M18,'能力値その他'!$C$1:$AD$1,0)-1)&IF(AND(INDEX('能力値その他'!$C$2:$AD$115, MATCH($A$1,'能力値その他'!$A$2:$A$115,0), MATCH(M18,'能力値その他'!$C$1:$AD$1,0)-1)>=11, INDEX('能力値その他'!$C$2:$AD$115, MATCH($A$1,'能力値その他'!$A$2:$A$115,0), MATCH(M18,'能力値その他'!$C$1:$AD$1,0)-1)<=13),"th",CHOOSE(MIN(5,RIGHT(INDEX('能力値その他'!$C$2:$AD$115, MATCH($A$1,'能力値その他'!$A$2:$A$115,0), MATCH(M18,'能力値その他'!$C$1:$AD$1,0)-1))+1),"th","st","nd","rd","th"))&"]")} -> 27.8 [76th]
A19: ='テンプレート'!A19 -> カベジャンプ | B19: FALSE | C19: ='テンプレート'!C19 -> 大着地 | D19: {=IF(INDEX('行動フレーム・能力値'!$C$2:$AD$115, MATCH($A$1,'行動フレーム・能力値'!$A$2:$A$115,0), MATCH(C19,'行動フレーム・能力値'!$C$1:$AD$1,0))="-", "-", INDEX('行動フレーム・能力値'!$C$2:$AD$115, MATCH($A$1,'行動フレーム・能力値'!$A$2:$A$115,0), MATCH(C19,'行動フレーム・能力値'!$C$1:$AD$1,0))&"F")} -> 5F | E19: ='テンプレート'!E19 -> 走行速度 | F19: {=IF(INDEX('行動フレーム・能力値'!$C$2:$AD$115, MATCH($A$1,'行動フレーム・能力値'!$A$2:$A$115,0), MATCH(E19,'行動フレーム・能力値'!$C$1:$AD$1,0))="-", "-", INDEX('行動フレーム・能力値'!$C$2:$AD$115, MATCH($A$1,'行動フレーム・能力値'!$A$2:$A$115,0), MATCH(E19,'行動フレーム・能力値'!$C$1:$AD$1,0))&" ["&INDEX('行動フレーム・能力値'!$C$2:$AD$115, MATCH($A$1,'行動フレーム・能力値'!$A$2:$A$115,0), MATCH(E19,'行動フレーム・能力値'!$C$1:$AD$1,0)-1)&IF(AND(INDEX('行動フレーム・能力値'!$C$2:$AD$115, MATCH($A$1,'行動フレーム・能力値'!$A$2:$A$115,0), MATCH(E19,'行動フレーム・能力値'!$C$1:$AD$1,0)-1)>=11, INDEX('行動フレーム・能力値'!$C$2:$AD$115, MATCH($A$1,'行動フレーム・能力値'!$A$2:$A$115,0), MATCH(E19,'行動フレーム・能力値'!$C$1:$AD$1,0)-1)<=13),"th",CHOOSE(MIN(5,RIGHT(INDEX('行動フレーム・能力値'!$C$2:$AD$115, MATCH($A$1,'行動フレーム・能力値'!$A$2:$A$115,0), MATCH(E19,'行動フレーム・能力値'!$C$1:$AD$1,0)-1))+1),"th","st","nd","rd","th"))&"]")} -> 1.534 [71st] | G19: ='テンプレート'!G19 -> 小J急降下滞空 | H19: {=IF(INDEX('行動フレーム・能力値'!$C$2:$AD$115, MATCH($A$1,'行動フレーム・能力値'!$A$2:$A$115,0), MATCH(G19,'行動フレーム・能力値'!$C$1:$AD$1,0))="-", "-", INDEX('行動フレーム・能力値'!$C$2:$AD$115, MATCH($A$1,'行動フレーム・能力値'!$A$2:$A$115,0), MATCH(G19,'行動フレーム・能力値'!$C$1:$AD$1,0))&"F")} -> 22F | K19: ='テンプレート'!K19 -> 地上抵抗 | L19: {=IF(INDEX('能力値その他'!$C$2:$AD$115, MATCH($A$1,'能力値その他'!$A$2:$A$115,0), MATCH(K19,'能力値その他'!$C$1:$AD$1,0))="-", "-", INDEX('能力値その他'!$C$2:$AD$115, MATCH($A$1,'能力値その他'!$A$2:$A$115,0), MATCH(K19,'能力値その他'!$C$1:$AD$1,0))&" ["&INDEX('能力値その他'!$C$2:$AD$115, MATCH($A$1,'能力値その他'!$A$2:$A$115,0), MATCH(K19,'能力値その他'!$C$1:$AD$1,0)-1)&IF(AND(INDEX('能力値その他'!$C$2:$AD$115, MATCH($A$1,'能力値その他'!$A$2:$A$115,0), MATCH(K19,'能力値その他'!$C$1:$AD$1,0)-1)>=11, INDEX('能力値その他'!$C$2:$AD$115, MATCH($A$1,'能力値その他'!$A$2:$A$115,0), MATCH(K19,'能力値その他'!$C$1:$AD$1,0)-1)<=13),"th",CHOOSE(MIN(5,RIGHT(INDEX('能力値その他'!$C$2:$AD$115, MATCH($A$1,'能力値その他'!$A$2:$A$115,0), MATCH(K19,'能力値その他'!$C$1:$AD$1,0)-1))+1),"th","st","nd","rd","th"))&"]")} -> 0.113 [34th] | M19: ='テンプレート'!M19 -> 小J高度 | N19: {=IF(INDEX('能力値その他'!$C$2:$AD$115, MATCH($A$1,'能力値その他'!$A$2:$A$115,0), MATCH(M19,'能力値その他'!$C$1:$AD$1,0))="-", "-", INDEX('能力値その他'!$C$2:$AD$115, MATCH($A$1,'能力値その他'!$A$2:$A$115,0), MATCH(M19,'能力値その他'!$C$1:$AD$1,0))&" ["&INDEX('能力値その他'!$C$2:$AD$115, MATCH($A$1,'能力値その他'!$A$2:$A$115,0), MATCH(M19,'能力値その他'!$C$1:$AD$1,0)-1)&IF(AND(INDEX('能力値その他'!$C$2:$AD$115, MATCH($A$1,'能力値その他'!$A$2:$A$115,0), MATCH(M19,'能力値その他'!$C$1:$AD$1,0)-1)>=11, INDEX('能力値その他'!$C$2:$AD$115, MATCH($A$1,'能力値その他'!$A$2:$A$115,0), MATCH(M19,'能力値その他'!$C$1:$AD$1,0)-1)<=13),"th",CHOOSE(MIN(5,RIGHT(INDEX('能力値その他'!$C$2:$AD$115, MATCH($A$1,'能力値その他'!$A$2:$A$115,0), MATCH(M19,'能力値その他'!$C$1:$AD$1,0)-1))+1),"th","st","nd","rd","th"))&"]")} -> 13.38 [76th]
A20: ='テンプレート'!A20 -> カベ張りつき | B20: FALSE | C20: 走行移行前F | D20: {=IF(INDEX('行動フレーム・能力値'!$C$2:$AD$115, MATCH($A$1,'行動フレーム・能力値'!$A$2:$A$115,0), MATCH(C20,'行動フレーム・能力値'!$C$1:$AD$1,0))="-", "-", INDEX('行動フレーム・能力値'!$C$2:$AD$115, MATCH($A$1,'行動フレーム・能力値'!$A$2:$A$115,0), MATCH(C20,'行動フレーム・能力値'!$C$1:$AD$1,0))&"F ["&INDEX('行動フレーム・能力値'!$C$2:$AD$115, MATCH($A$1,'行動フレーム・能力値'!$A$2:$A$115,0), MATCH(C20,'行動フレーム・能力値'!$C$1:$AD$1,0)-1)&IF(AND(INDEX('行動フレーム・能力値'!$C$2:$AD$115, MATCH($A$1,'行動フレーム・能力値'!$A$2:$A$115,0), MATCH(C20,'行動フレーム・能力値'!$C$1:$AD$1,0)-1)>=11, INDEX('行動フレーム・能力値'!$C$2:$AD$115, MATCH($A$1,'行動フレーム・能力値'!$A$2:$A$115,0), MATCH(C20,'行動フレーム・能力値'!$C$1:$AD$1,0)-1)<=13),"th",CHOOSE(MIN(5,RIGHT(INDEX('行動フレーム・能力値'!$C$2:$AD$115, MATCH($A$1,'行動フレーム・能力値'!$A$2:$A$115,0), MATCH(C20,'行動フレーム・能力値'!$C$1:$AD$1,0)-1))+1),"th","st","nd","rd","th"))&"]")} -> 12F [62nd] | E20: ='テンプレート'!E20 -> 空中速度 | F20: {=IF(INDEX('行動フレーム・能力値'!$C$2:$AD$115, MATCH($A$1,'行動フレーム・能力値'!$A$2:$A$115,0), MATCH(E20,'行動フレーム・能力値'!$C$1:$AD$1,0))="-", "-", INDEX('行動フレーム・能力値'!$C$2:$AD$115, MATCH($A$1,'行動フレーム・能力値'!$A$2:$A$115,0), MATCH(E20,'行動フレーム・能力値'!$C$1:$AD$1,0))&" ["&INDEX('行動フレーム・能力値'!$C$2:$AD$115, MATCH($A$1,'行動フレーム・能力値'!$A$2:$A$115,0), MATCH(E20,'行動フレーム・能力値'!$C$1:$AD$1,0)-1)&IF(AND(INDEX('行動フレーム・能力値'!$C$2:$AD$115, MATCH($A$1,'行動フレーム・能力値'!$A$2:$A$115,0), MATCH(E20,'行動フレーム・能力値'!$C$1:$AD$1,0)-1)>=11, INDEX('行動フレーム・能力値'!$C$2:$AD$115, MATCH($A$1,'行動フレーム・能力値'!$A$2:$A$115,0), MATCH(E20,'行動フレーム・能力値'!$C$1:$AD$1,0)-1)<=13),"th",CHOOSE(MIN(5,RIGHT(INDEX('行動フレーム・能力値'!$C$2:$AD$115, MATCH($A$1,'行動フレーム・能力値'!$A$2:$A$115,0), MATCH(E20,'行動フレーム・能力値'!$C$1:$AD$1,0)-1))+1),"th","st","nd","rd","th"))&"]")} -> 0.924 [75th] | G20: ='テンプレート'!G20 -> 大J急降下滞空 | H20: {=IF(INDEX('行動フレーム・能力値'!$C$2:$AD$115, MATCH($A$1,'行動フレーム・能力値'!$A$2:$A$115,0), MATCH(G20,'行動フレーム・能力値'!$C$1:$AD$1,0))="-", "-", INDEX('行動フレーム・能力値'!$C$2:$AD$115, MATCH($A$1,'行動フレーム・能力値'!$A$2:$A$115,0), MATCH(G20,'行動フレーム・能力値'!$C$1:$AD$1,0))&"F")} -> 30F | K20: ='テンプレート'!K20 -> 空中加速 | L20: {=IF(INDEX('能力値その他'!$C$2:$AD$115, MATCH($A$1,'能力値その他'!$A$2:$A$115,0), MATCH(K20,'能力値その他'!$C$1:$AD$1,0))="-", "-", INDEX('能力値その他'!$C$2:$AD$115, MATCH($A$1,'能力値その他'!$A$2:$A$115,0), MATCH(K20,'能力値その他'!$C$1:$AD$1,0))&" ["&INDEX('能力値その他'!$C$2:$AD$115, MATCH($A$1,'能力値その他'!$A$2:$A$115,0), MATCH(K20,'能力値その他'!$C$1:$AD$1,0)-1)&IF(AND(INDEX('能力値その他'!$C$2:$AD$115, MATCH($A$1,'能力値その他'!$A$2:$A$115,0), MATCH(K20,'能力値その他'!$C$1:$AD$1,0)-1)>=11, INDEX('能力値その他'!$C$2:$AD$115, MATCH($A$1,'能力値その他'!$A$2:$A$115,0), MATCH(K20,'能力値その他'!$C$1:$AD$1,0)-1)<=13),"th",CHOOSE(MIN(5,RIGHT(INDEX('能力値その他'!$C$2:$AD$115, MATCH($A$1,'能力値その他'!$A$2:$A$115,0), MATCH(K20,'能力値その他'!$C$1:$AD$1,0)-1))+1),"th","st","nd","rd","th"))&"]")} -> 0.05 [70th] | M20: ='テンプレート'!M20 -> 空中J高度 | N20: {=IF(INDEX('能力値その他'!$C$2:$AD$115, MATCH($A$1,'能力値その他'!$A$2:$A$115,0), MATCH(M20,'能力値その他'!$C$1:$AD$1,0))="-", "-", INDEX('能力値その他'!$C$2:$AD$115, MATCH($A$1,'能力値その他'!$A$2:$A$115,0), MATCH(M20,'能力値その他'!$C$1:$AD$1,0))&" ["&INDEX('能力値その他'!$C$2:$AD$115, MATCH($A$1,'能力値その他'!$A$2:$A$115,0), MATCH(M20,'能力値その他'!$C$1:$AD$1,0)-1)&IF(AND(INDEX('能力値その他'!$C$2:$AD$115, MATCH($A$1,'能力値その他'!$A$2:$A$115,0), MATCH(M20,'能力値その他'!$C$1:$AD$1,0)-1)>=11, INDEX('能力値その他'!$C$2:$AD$115, MATCH($A$1,'能力値その他'!$A$2:$A$115,0), MATCH(M20,'能力値その他'!$C$1:$AD$1,0)-1)<=13),"th",CHOOSE(MIN(5,RIGHT(INDEX('能力値その他'!$C$2:$AD$115, MATCH($A$1,'能力値その他'!$A$2:$A$115,0), MATCH(M20,'能力値その他'!$C$1:$AD$1,0)-1))+1),"th","st","nd","rd","th"))&"]")} -> 29 [67th]
A21: ='テンプレート'!A21 -> 空中ワイヤー | B21: FALSE | C21: ='テンプレート'!C21 -> ステップ全体F | D21: {=IF(INDEX('行動フレーム・能力値'!$C$2:$AD$115, MATCH($A$1,'行動フレーム・能力値'!$A$2:$A$115,0), MATCH(C21,'行動フレーム・能力値'!$C$1:$AD$1,0))="-", "-", INDEX('行動フレーム・能力値'!$C$2:$AD$115, MATCH($A$1,'行動フレーム・能力値'!$A$2:$A$115,0), MATCH(C21,'行動フレーム・能力値'!$C$1:$AD$1,0))&"F ["&INDEX('行動フレーム・能力値'!$C$2:$AD$115, MATCH($A$1,'行動フレーム・能力値'!$A$2:$A$115,0), MATCH(C21,'行動フレーム・能力値'!$C$1:$AD$1,0)-1)&IF(AND(INDEX('行動フレーム・能力値'!$C$2:$AD$115, MATCH($A$1,'行動フレーム・能力値'!$A$2:$A$115,0), MATCH(C21,'行動フレーム・能力値'!$C$1:$AD$1,0)-1)>=11, INDEX('行動フレーム・能力値'!$C$2:$AD$115, MATCH($A$1,'行動フレーム・能力値'!$A$2:$A$115,0), MATCH(C21,'行動フレーム・能力値'!$C$1:$AD$1,0)-1)<=13),"th",CHOOSE(MIN(5,RIGHT(INDEX('行動フレーム・能力値'!$C$2:$AD$115, MATCH($A$1,'行動フレーム・能力値'!$A$2:$A$115,0), MATCH(C21,'行動フレーム・能力値'!$C$1:$AD$1,0)-1))+1),"th","st","nd","rd","th"))&"]")} -> 19F [13th] | E21: ='テンプレート'!E21 -> 落下速度 | F21: {=IF(INDEX('行動フレーム・能力値'!$C$2:$AD$115, MATCH($A$1,'行動フレーム・能力値'!$A$2:$A$115,0), MATCH(E21,'行動フレーム・能力値'!$C$1:$AD$1,0))="-", "-", INDEX('行動フレーム・能力値'!$C$2:$AD$115, MATCH($A$1,'行動フレーム・能力値'!$A$2:$A$115,0), MATCH(E21,'行動フレーム・能力値'!$C$1:$AD$1,0))&" ["&INDEX('行動フレーム・能力値'!$C$2:$AD$115, MATCH($A$1,'行動フレーム・能力値'!$A$2:$A$115,0), MATCH(E21,'行動フレーム・能力値'!$C$1:$AD$1,0)-1)&IF(AND(INDEX('行動フレーム・能力値'!$C$2:$AD$115, MATCH($A$1,'行動フレーム・能力値'!$A$2:$A$115,0), MATCH(E21,'行動フレーム・能力値'!$C$1:$AD$1,0)-1)>=11, INDEX('行動フレーム・能力値'!$C$2:$AD$115, MATCH($A$1,'行動フレーム・能力値'!$A$2:$A$115,0), MATCH(E21,'行動フレーム・能力値'!$C$1:$AD$1,0)-1)<=13),"th",CHOOSE(MIN(5,RIGHT(INDEX('行動フレーム・能力値'!$C$2:$AD$115, MATCH($A$1,'行動フレーム・能力値'!$A$2:$A$115,0), MATCH(E21,'行動フレーム・能力値'!$C$1:$AD$1,0)-1))+1),"th","st","nd","rd","th"))&"]")} -> 1.6 [43rd] | K21: ='テンプレート'!K21 -> 空中抵抗 | L21: {=IF(INDEX('能力値その他'!$C$2:$AD$115, MATCH($A$1,'能力値その他'!$A$2:$A$115,0), MATCH(K21,'能力値その他'!$C$1:$AD$1,0))="-", "-", INDEX('能力値その他'!$C$2:$AD$115, MATCH($A$1,'能力値その他'!$A$2:$A$115,0), MATCH(K21,'能力値その他'!$C$1:$AD$1,0))&" ["&INDEX('能力値その他'!$C$2:$AD$115, MATCH($A$1,'能力値その他'!$A$2:$A$115,0), MATCH(K21,'能力値その他'!$C$1:$AD$1,0)-1)&IF(AND(INDEX('能力値その他'!$C$2:$AD$115, MATCH($A$1,'能力値その他'!$A$2:$A$115,0), MATCH(K21,'能力値その他'!$C$1:$AD$1,0)-1)>=11, INDEX('能力値その他'!$C$2:$AD$115, MATCH($A$1,'能力値その他'!$A$2:$A$115,0), MATCH(K21,'能力値その他'!$C$1:$AD$1,0)-1)<=13),"th",CHOOSE(MIN(5,RIGHT(INDEX('能力値その他'!$C$2:$AD$115, MATCH($A$1,'能力値その他'!$A$2:$A$115,0), MATCH(K21,'能力値その他'!$C$1:$AD$1,0)-1))+1),"th","st","nd","rd","th"))&"]")} -> 0.0038 [85th]
